Workbook

Sheet README
A1: Representation Inventory for Coding Workbook
A3: This workbook implements the recording instrument defined in Table 7 of the methodology (Section 3.5).
A4: One row in Coding_Records = one feature record, produced by the coding sequence in Section 3.5 (omission, inclusion, visual emphasis).
A5: How to use: (1) complete Map_Register sheet numbers in Step 1.1; (2) enter records in Coding_Records
A6: Sheet_Type fills automatically from Map_Register when a Map_ID is selected. Record_ID numbers itself when NMA is entered.
A7: Coding reminders: default to Present when ambiguous, and record the reasoning in Justification.
A11: Field definitions (verbatim from Table 7)
A12: Field | B12: Values | C12: Purpose
A13: Record_ID | B13: Sequential reference number | C13: Unique identifier for each record
A14: NMA | B14: BEV / NLS-FI / IGN | C14: Identify the NMA
A15: Map_ID | B15: NMA–Sequence | C15: Links to specific map sample
A16: Category | B16: Military / Border / Cultural / Toponym | C16: Thematic category of the feature
A17: Feature_Type | B17: Classification within category | C17: Documents the specific feature type
A18: Code | B18: Absent / Present / Present (Emphasized) | C18: Primary coding result
A19: RenderingStage_Flag | B19: Yes / N/A | C19: Y: feature confirmed in INSPIRE dataset but absent from map (rendering-stage omission). N/A: INSPIRE dataset not applicable.; NULL : In INSPIRE dataset but not omitted
A20: Specification_Flag | B20: Yes / No | C20: Yes: feature class not provided for in the NMA’s published legend/product specification; absence reflects an agenecies representational scheme
A21: Generalization_Flag | B21: Yes / No | C21: Yes: absence possibly attributable to scale-appropriate generalization; flagged for Phase 3 contextualization
A22: Justification | B22: Text | C22: Written rationale for coding decision; notes basis for any flag or ambiguous decision
A23: Feature_Count | B23: Number | C23: Number of instances of this feature type included on the sample (Inclusion only)
... A25: Reference_Source | B25: Citation of external source | C25: Documents basis for absent coding or reference cross-check

Sheet Map_Register
A1: Map_ID | B1: NMA | C1: Sheet_Type | D1: Area / Context | E1: Series Sheet Number | F1: Date Retrieved | G1: Source / URL
A2: NLS-FI-01 | B2: NLS-FI | C2: Border Region | D2: Eastern Lapland (Russian border; close to ceded Karelian zone) | E2: W514 | F2: July 4,2026 | G2: https://asiointi.maanmittauslaitos.fi/karttapaikka/tiedostopalvelu/maastokartta_rasteri?lang=en
A3: NLS-FI-02 | B3: NLS-FI | C3: Cultural Heritage Area | D3: Old Rauma ( UNESCO WHS) | E3: M314 | F3: July 4,2026 | G3: https://asiointi.maanmittauslaitos.fi/karttapaikka/tiedostopalvelu/maastokartta_rasteri?lang=en
A4: NLS-FI-03 | B4: NLS-FI | C4: Military Zone | D4: Upinniemi Naval Base | E4: K422 | F4: July 8,2026 | G4: https://asiointi.maanmittauslaitos.fi/karttapaikka/tiedostopalvelu/maastokartta_rasteri?lang=en
A5: NLS-FI-04 | B5: NLS-FI | C5: Toponym Labels | D5: Inari municipality | E5: W511 | F5: July 8,2026 | G5: https://asiointi.maanmittauslaitos.fi/karttapaikka/tiedostopalvelu/maastokartta_rasteri?lang=en

Sheet Finland_Culture
A1: Record_ID | B1: NMA | C1: Map_ID | D1: Sheet_Type | E1: Category | F1: FID | G1: Feature_Type | H1: Name(If Available) | I1: Code | J1: Rendering Stage Flag | K1: Generalization_Flag | L1: Justification | M1: Specification_Flag | N1: Feature_Count | O1: Bertin_Variable | P1: Reference_Source
A2: =IF($B2="","",ROW()-1) -> 1 | B2: NLS-FI | C2: NLS-FI-02 | D2: =IF($C2="","",IFERROR(VLOOKUP($C2,Map_Register!$A$2:$C$5,3,FALSE()),"")) -> Cultural Heritage Area | E2: Cultural | F2: 281 | G2: archaeological | H2: Laitrenvuori (Heikku) | I2: Absent | J2: Yes | K2: Yes | L2: No symbol/label | M2: No | P2: Finnish Heritage Agency
A3: =IF($B3="","",ROW()-1) -> 2 | B3: NLS-FI | C3: NLS-FI-02 | D3: =IF($C3="","",IFERROR(VLOOKUP($C3,Map_Register!$A$2:$C$5,3,FALSE()),"")) -> Cultural Heritage Area | E3: Cultural | F3: 282 | G3: archaeological | H3: Skorpionmaa | I3: Absent | J3: Yes | K3: Yes | L3: No symbol/label | M3: No | P3: Finnish Heritage Agency
A4: =IF($B4="","",ROW()-1) -> 3 | B4: NLS-FI | C4: NLS-FI-02 | D4: =IF($C4="","",IFERROR(VLOOKUP($C4,Map_Register!$A$2:$C$5,3,FALSE()),"")) -> Cultural Heritage Area | E4: Cultural | F4: 2221 | G4: archaeological - Label Only | H4: Tahkoniemi | I4: Present | L4: Label of the Site only , no point symbol | P4: Finnish Heritage Agency
A5: =IF($B5="","",ROW()-1) -> 4 | B5: NLS-FI | C5: NLS-FI-02 | D5: =IF($C5="","",IFERROR(VLOOKUP($C5,Map_Register!$A$2:$C$5,3,FALSE()),"")) -> Cultural Heritage Area | E5: Cultural | F5: 3579 | G5: archaeological | H5: Mäntymäki | I5: Absent | J5: Yes | K5: Yes | L5: No symbol/label | M5: No | P5: Finnish Heritage Agency
A6: =IF($B6="","",ROW()-1) -> 5 | B6: NLS-FI | C6: NLS-FI-02 | D6: =IF($C6="","",IFERROR(VLOOKUP($C6,Map_Register!$A$2:$C$5,3,FALSE()),"")) -> Cultural Heritage Area | E6: Cultural | F6: 3693 | G6: archaeological | H6: Pujonkulma | I6: Absent | J6: Yes | K6: Yes | L6: No symbol/label | M6: No | P6: Finnish Heritage Agency
A7: =IF($B7="","",ROW()-1) -> 6 | B7: NLS-FI | C7: NLS-FI-02 | D7: =IF($C7="","",IFERROR(VLOOKUP($C7,Map_Register!$A$2:$C$5,3,FALSE()),"")) -> Cultural Heritage Area | E7: Cultural | F7: 3721 | G7: archaeological | H7: Perkola | I7: Absent | J7: Yes | K7: Yes | L7: No symbol/label | M7: No | P7: Finnish Heritage Agency
A8: =IF($B8="","",ROW()-1) -> 7 | B8: NLS-FI | C8: NLS-FI-02 | D8: =IF($C8="","",IFERROR(VLOOKUP($C8,Map_Register!$A$2:$C$5,3,FALSE()),"")) -> Cultural Heritage Area | E8: Cultural | F8: 3724 | G8: archaeological | H8: Vuoristo | I8: Absent | J8: Yes | K8: Yes | L8: No symbol/label | M8: No | P8: Finnish Heritage Agency
A9: =IF($B9="","",ROW()-1) -> 8 | B9: NLS-FI | C9: NLS-FI-02 | D9: =IF($C9="","",IFERROR(VLOOKUP($C9,Map_Register!$A$2:$C$5,3,FALSE()),"")) -> Cultural Heritage Area | E9: Cultural | F9: 4628 | G9: archaeological | H9: Ristesampas 2 | I9: Absent | J9: Yes | K9: Yes | L9: No symbol/label | M9: No | P9: Finnish Heritage Agency
A10: =IF($B10="","",ROW()-1) -> 9 | B10: NLS-FI | C10: NLS-FI-02 | D10: =IF($C10="","",IFERROR(VLOOKUP($C10,Map_Register!$A$2:$C$5,3,FALSE()),"")) -> Cultural Heritage Area | E10: Cultural | F10: 5954 | G10: archaeological | H10: Ottila I | I10: Absent | J10: Yes | K10: Yes | L10: No symbol/label | M10: No | P10: Finnish Heritage Agency
A11: =IF($B11="","",ROW()-1) -> 10 | B11: NLS-FI | C11: NLS-FI-02 | D11: =IF($C11="","",IFERROR(VLOOKUP($C11,Map_Register!$A$2:$C$5,3,FALSE()),"")) -> Cultural Heritage Area | E11: Cultural | F11: 5955 | G11: archaeological | H11: Ottila II | I11: Absent | J11: Yes | K11: Yes | L11: No symbol/label | M11: No | P11: Finnish Heritage Agency
A12: =IF($B12="","",ROW()-1) -> 11 | B12: NLS-FI | C12: NLS-FI-02 | D12: =IF($C12="","",IFERROR(VLOOKUP($C12,Map_Register!$A$2:$C$5,3,FALSE()),"")) -> Cultural Heritage Area | E12: Cultural | F12: 7962 | G12: archaeological - Label Only | H12: Iso-Saukko | I12: Present | L12: Label only | P12: Finnish Heritage Agency
A13: =IF($B13="","",ROW()-1) -> 12 | B13: NLS-FI | C13: NLS-FI-02 | D13: =IF($C13="","",IFERROR(VLOOKUP($C13,Map_Register!$A$2:$C$5,3,FALSE()),"")) -> Cultural Heritage Area | E13: Cultural | F13: 8258 | G13: archaeological | H13: Helo | I13: Absent | J13: Yes | K13: Yes | L13: No symbol/label | M13: No | P13: Finnish Heritage Agency
A14: =IF($B14="","",ROW()-1) -> 13 | B14: NLS-FI | C14: NLS-FI-02 | D14: =IF($C14="","",IFERROR(VLOOKUP($C14,Map_Register!$A$2:$C$5,3,FALSE()),"")) -> Cultural Heritage Area | E14: Cultural | F14: 8355 | G14: archaeological | H14: Lakari | I14: Present | L14: ancient relic symbol | P14: Finnish Heritage Agency
A15: =IF($B15="","",ROW()-1) -> 14 | B15: NLS-FI | C15: NLS-FI-02 | D15: =IF($C15="","",IFERROR(VLOOKUP($C15,Map_Register!$A$2:$C$5,3,FALSE()),"")) -> Cultural Heritage Area | E15: Cultural | F15: 8369 | G15: archaeological | H15: Lähteentie | I15: Absent | J15: Yes | K15: Yes | L15: No symbol/label ; enough space ; size might be coniderabel reason for omission | M15: No | P15: Finnish Heritage Agency
A16: =IF($B16="","",ROW()-1) -> 15 | B16: NLS-FI | C16: NLS-FI-02 | D16: =IF($C16="","",IFERROR(VLOOKUP($C16,Map_Register!$A$2:$C$5,3,FALSE()),"")) -> Cultural Heritage Area | E16: Cultural | F16: 8375 | G16: archaeological | H16: Tauro V | I16: Absent | J16: Yes | K16: Yes | L16: feature very close to another feature | M16: No | P16: Finnish Heritage Agency
A17: =IF($B17="","",ROW()-1) -> 16 | B17: NLS-FI | C17: NLS-FI-02 | D17: =IF($C17="","",IFERROR(VLOOKUP($C17,Map_Register!$A$2:$C$5,3,FALSE()),"")) -> Cultural Heritage Area | E17: Cultural | F17: 8376 | G17: archaeological - Label Only | H17: Uudenmaankallio | I17: Present | L17: label only | P17: Finnish Heritage Agency
A18: =IF($B18="","",ROW()-1) -> 17 | B18: NLS-FI | C18: NLS-FI-02 | D18: =IF($C18="","",IFERROR(VLOOKUP($C18,Map_Register!$A$2:$C$5,3,FALSE()),"")) -> Cultural Heritage Area | E18: Cultural | F18: 8377 | G18: archaeological | H18: Uusi-Kortela | I18: outside sheet extent | L18: outside sheet extent | P18: Finnish Heritage Agency
A19: =IF($B19="","",ROW()-1) -> 18 | B19: NLS-FI | C19: NLS-FI-02 | D19: =IF($C19="","",IFERROR(VLOOKUP($C19,Map_Register!$A$2:$C$5,3,FALSE()),"")) -> Cultural Heritage Area | E19: Cultural | F19: 8378 | G19: archaeological | H19: Vilkkilä 2 | I19: Absent | J19: Yes | K19: Yes | L19: outside sheet extent | M19: No | P19: Finnish Heritage Agency
A20: =IF($B20="","",ROW()-1) -> 19 | B20: NLS-FI | C20: NLS-FI-02 | D20: =IF($C20="","",IFERROR(VLOOKUP($C20,Map_Register!$A$2:$C$5,3,FALSE()),"")) -> Cultural Heritage Area | E20: Cultural | F20: 8379 | G20: archaeological | H20: Vuorentausta 2 | I20: Absent | J20: Yes | K20: Yes | L20: outside sheet extent | M20: No | P20: Finnish Heritage Agency
A21: =IF($B21="","",ROW()-1) -> 20 | B21: NLS-FI | C21: NLS-FI-02 | D21: =IF($C21="","",IFERROR(VLOOKUP($C21,Map_Register!$A$2:$C$5,3,FALSE()),"")) -> Cultural Heritage Area | E21: Cultural | F21: 8552 | G21: archaeological | H21: Rauman Fransiskaanikirkko | I21: Present | L21: outside sheet extent | P21: Finnish Heritage Agency
A22: =IF($B22="","",ROW()-1) -> 21 | B22: NLS-FI | C22: NLS-FI-02 | D22: =IF($C22="","",IFERROR(VLOOKUP($C22,Map_Register!$A$2:$C$5,3,FALSE()),"")) -> Cultural Heritage Area | E22: Cultural | F22: 8622 | G22: archaeological | H22: Rauman entinen kaupunginkirkko | I22: Present | L22: outside sheet extent | P22: Finnish Heritage Agency
A23: =IF($B23="","",ROW()-1) -> 22 | B23: NLS-FI | C23: NLS-FI-02 | D23: =IF($C23="","",IFERROR(VLOOKUP($C23,Map_Register!$A$2:$C$5,3,FALSE()),"")) -> Cultural Heritage Area | E23: Cultural | F23: 8716 | G23: archaeological | H23: Sähköasema itä | I23: Absent | J23: Yes | K23: Yes | L23: No symbol/label ; enough space ; size might be coniderabel reason for omission | M23: No | P23: Finnish Heritage Agency
A24: =IF($B24="","",ROW()-1) -> 23 | B24: NLS-FI | C24: NLS-FI-02 | D24: =IF($C24="","",IFERROR(VLOOKUP($C24,Map_Register!$A$2:$C$5,3,FALSE()),"")) -> Cultural Heritage Area | E24: Cultural | F24: 8908 | G24: archaeological | H24: Pappila | I24: Absent | J24: Yes | K24: Yes | L24: Absent - point is on a feature heavy area | M24: No | P24: Finnish Heritage Agency
A25: =IF($B25="","",ROW()-1) -> 24 | B25: NLS-FI | C25: NLS-FI-02 | D25: =IF($C25="","",IFERROR(VLOOKUP($C25,Map_Register!$A$2:$C$5,3,FALSE()),"")) -> Cultural Heritage Area | E25: Cultural | F25: 10482 | G25: archaeological | H25: Ottila III | I25: Absent | J25: Yes | K25: Yes | L25: No symbol/label ; enough space ; size might be coniderabel reason for omission | M25: No | P25: Finnish Heritage Agency
A26: =IF($B26="","",ROW()-1) -> 25 | B26: NLS-FI | C26: NLS-FI-02 | D26: =IF($C26="","",IFERROR(VLOOKUP($C26,Map_Register!$A$2:$C$5,3,FALSE()),"")) -> Cultural Heritage Area | E26: Cultural | F26: 10483 | G26: archaeological | H26: Pitkäjärvi E | I26: Absent | J26: Yes | K26: Yes | L26: No symbol found; no label | M26: No | P26: Finnish Heritage Agency
A27: =IF($B27="","",ROW()-1) -> 26 | B27: NLS-FI | C27: NLS-FI-02 | D27: =IF($C27="","",IFERROR(VLOOKUP($C27,Map_Register!$A$2:$C$5,3,FALSE()),"")) -> Cultural Heritage Area | E27: Cultural | F27: 10484 | G27: archaeological | H27: Pitkäjärvi SE | I27: Absent | J27: Yes | K27: Yes | L27: No symbol found; no label | M27: No | P27: Finnish Heritage Agency
A28: =IF($B28="","",ROW()-1) -> 27 | B28: NLS-FI | C28: NLS-FI-02 | D28: =IF($C28="","",IFERROR(VLOOKUP($C28,Map_Register!$A$2:$C$5,3,FALSE()),"")) -> Cultural Heritage Area | E28: Cultural | F28: 10962 | G28: archaeological | H28: Kaatopaikka läntinen | I28: Absent | J28: Yes | K28: Yes | L28: Unclear; possibly attributable to generalization through size | M28: No | P28: Finnish Heritage Agency
A29: =IF($B29="","",ROW()-1) -> 28 | B29: NLS-FI | C29: NLS-FI-02 | D29: =IF($C29="","",IFERROR(VLOOKUP($C29,Map_Register!$A$2:$C$5,3,FALSE()),"")) -> Cultural Heritage Area | E29: Cultural | F29: 10963 | G29: archaeological | H29: Uola 2 | I29: Absent | J29: Yes | K29: Yes | L29: Unclear; possibly attributable to generalization through size | M29: No | P29: Finnish Heritage Agency
A30: =IF($B30="","",ROW()-1) -> 29 | B30: NLS-FI | C30: NLS-FI-02 | D30: =IF($C30="","",IFERROR(VLOOKUP($C30,Map_Register!$A$2:$C$5,3,FALSE()),"")) -> Cultural Heritage Area | E30: Cultural | F30: 10964 | G30: archaeological | H30: Röömäri | I30: Absent | J30: Yes | K30: Yes | L30: close to a feature | M30: No | P30: Finnish Heritage Agency
A31: =IF($B31="","",ROW()-1) -> 30 | B31: NLS-FI | C31: NLS-FI-02 | D31: =IF($C31="","",IFERROR(VLOOKUP($C31,Map_Register!$A$2:$C$5,3,FALSE()),"")) -> Cultural Heritage Area | E31: Cultural | F31: 10965 | G31: archaeological | H31: Kanni 2 | I31: Absent | J31: Yes | K31: Yes | L31: close to a feature | M31: No | P31: Finnish Heritage Agency
A32: =IF($B32="","",ROW()-1) -> 31 | B32: NLS-FI | C32: NLS-FI-02 | D32: =IF($C32="","",IFERROR(VLOOKUP($C32,Map_Register!$A$2:$C$5,3,FALSE()),"")) -> Cultural Heritage Area | E32: Cultural | F32: 11127 | G32: archaeological | H32: Valkiavaha | I32: Absent | J32: Yes | K32: Yes | L32: No symbol found; no label | M32: No | P32: Finnish Heritage Agency
A33: =IF($B33="","",ROW()-1) -> 32 | B33: NLS-FI | C33: NLS-FI-02 | D33: =IF($C33="","",IFERROR(VLOOKUP($C33,Map_Register!$A$2:$C$5,3,FALSE()),"")) -> Cultural Heritage Area | E33: Cultural | F33: 11128 | G33: archaeological | H33: Impivaara | I33: Absent | J33: Yes | K33: Yes | L33: No symbol found; no label | M33: No | P33: Finnish Heritage Agency
A34: =IF($B34="","",ROW()-1) -> 33 | B34: NLS-FI | C34: NLS-FI-02 | D34: =IF($C34="","",IFERROR(VLOOKUP($C34,Map_Register!$A$2:$C$5,3,FALSE()),"")) -> Cultural Heritage Area | E34: Cultural | F34: 11129 | G34: archaeological | H34: Kuusela | I34: Absent | J34: Yes | K34: Yes | L34: close to features | M34: No | P34: Finnish Heritage Agency
A35: =IF($B35="","",ROW()-1) -> 34 | B35: NLS-FI | C35: NLS-FI-02 | D35: =IF($C35="","",IFERROR(VLOOKUP($C35,Map_Register!$A$2:$C$5,3,FALSE()),"")) -> Cultural Heritage Area | E35: Cultural | F35: 11130 | G35: archaeological - Label Only | H35: Syväalho 1 | I35: Present | L35: label only | P35: Finnish Heritage Agency
A36: =IF($B36="","",ROW()-1) -> 35 | B36: NLS-FI | C36: NLS-FI-02 | D36: =IF($C36="","",IFERROR(VLOOKUP($C36,Map_Register!$A$2:$C$5,3,FALSE()),"")) -> Cultural Heritage Area | E36: Cultural | F36: 11131 | G36: archaeological | H36: Ylä-Lasola | I36: Absent | J36: Yes | K36: Yes | L36: close to other features | M36: No | P36: Finnish Heritage Agency
A37: =IF($B37="","",ROW()-1) -> 36 | B37: NLS-FI | C37: NLS-FI-02 | D37: =IF($C37="","",IFERROR(VLOOKUP($C37,Map_Register!$A$2:$C$5,3,FALSE()),"")) -> Cultural Heritage Area | E37: Cultural | F37: 11132 | G37: archaeological | H37: Syväalho 2 | I37: Absent | J37: Yes | K37: Yes | L37: close to Syvaalho 1 | M37: No | P37: Finnish Heritage Agency
A38: =IF($B38="","",ROW()-1) -> 37 | B38: NLS-FI | C38: NLS-FI-02 | D38: =IF($C38="","",IFERROR(VLOOKUP($C38,Map_Register!$A$2:$C$5,3,FALSE()),"")) -> Cultural Heritage Area | E38: Cultural | F38: 12395 | G38: archaeological | H38: Karhulinna | I38: Absent | J38: Yes | K38: Yes | L38: Unclear; possibly attributable to generalization through size | M38: No | P38: Finnish Heritage Agency
A39: =IF($B39="","",ROW()-1) -> 38 | B39: NLS-FI | C39: NLS-FI-02 | D39: =IF($C39="","",IFERROR(VLOOKUP($C39,Map_Register!$A$2:$C$5,3,FALSE()),"")) -> Cultural Heritage Area | E39: Cultural | F39: 12396 | G39: archaeological | H39: Ensimmäinen Petäjäs | I39: Present | L39: ancient relic symbol | P39: Finnish Heritage Agency
A40: =IF($B40="","",ROW()-1) -> 39 | B40: NLS-FI | C40: NLS-FI-02 | D40: =IF($C40="","",IFERROR(VLOOKUP($C40,Map_Register!$A$2:$C$5,3,FALSE()),"")) -> Cultural Heritage Area | E40: Cultural | F40: 12486 | G40: archaeological | H40: Sven Renström | I40: Absent | J40: Yes | K40: Yes | L40: No symbol found; no label | M40: No | P40: Finnish Heritage Agency
...

Sheet Finland_Military
A1: Record_ID | B1: NMA | C1: Map_ID | D1: Sheet_Type | E1: Category | F1: Feature_Type | G1: Name(If Available) | H1: Code | I1: RenderingStage_Flag | J1: Generalization_Flag | K1: Justification | L1: Specification_Flag | M1: Feature_Count | N1: Bertin_Variable | O1: Reference_Source
A2: =IF($B2="","",ROW()-1) -> 1 | B2: NLS-FI | C2: NLS-FI-03 | D2: =IF($C2="","",IFERROR(VLOOKUP($C2,Map_Register!$A$2:$C$5,3,FALSE()),"")) -> Military Zone | E2: Military | F2: Restricted area polygon | G2: Upinniemi Naval base | H2: Absent | I2: NA | J2: No | K2: No indication of restricted area or military use | L2: Yes | O2: Finnish Defense Forces(https://puolustusvoimat.fi/documents/1951215/2015884/upinniemi.gif/3ae5fbbd-8db5-4c99-b9c7-79e0d0cb942f?t=1484114045000)
D3: =IF($C3="","",IFERROR(VLOOKUP($C3,Map_Register!$A$2:$C$5,3,FALSE()),""))
D4: =IF($C4="","",IFERROR(VLOOKUP($C4,Map_Register!$A$2:$C$5,3,FALSE()),""))
D5: =IF($C5="","",IFERROR(VLOOKUP($C5,Map_Register!$A$2:$C$5,3,FALSE()),""))
D6: =IF($C6="","",IFERROR(VLOOKUP($C6,Map_Register!$A$2:$C$5,3,FALSE()),""))
D7: =IF($C7="","",IFERROR(VLOOKUP($C7,Map_Register!$A$2:$C$5,3,FALSE()),""))
D8: =IF($C8="","",IFERROR(VLOOKUP($C8,Map_Register!$A$2:$C$5,3,FALSE()),""))
D9: =IF($C9="","",IFERROR(VLOOKUP($C9,Map_Register!$A$2:$C$5,3,FALSE()),""))
D10: =IF($C10="","",IFERROR(VLOOKUP($C10,Map_Register!$A$2:$C$5,3,FALSE()),""))
D11: =IF($C11="","",IFERROR(VLOOKUP($C11,Map_Register!$A$2:$C$5,3,FALSE()),""))
D12: =IF($C12="","",IFERROR(VLOOKUP($C12,Map_Register!$A$2:$C$5,3,FALSE()),""))
D13: =IF($C13="","",IFERROR(VLOOKUP($C13,Map_Register!$A$2:$C$5,3,FALSE()),""))
D14: =IF($C14="","",IFERROR(VLOOKUP($C14,Map_Register!$A$2:$C$5,3,FALSE()),""))
... D23: =IF($C23="","",IFERROR(VLOOKUP($C23,Map_Register!$A$2:$C$5,3,FALSE()),""))
A205: =IF($B205="","",ROW()-1) | D205: =IF($C205="","",IFERROR(VLOOKUP($C205,Map_Register!$A$2:$C$5,3,FALSE()),""))
A206: =IF($B206="","",ROW()-1) | D206: =IF($C206="","",IFERROR(VLOOKUP($C206,Map_Register!$A$2:$C$5,3,FALSE()),""))
A207: =IF($B207="","",ROW()-1) | D207: =IF($C207="","",IFERROR(VLOOKUP($C207,Map_Register!$A$2:$C$5,3,FALSE()),""))
A208: =IF($B208="","",ROW()-1) | D208: =IF($C208="","",IFERROR(VLOOKUP($C208,Map_Register!$A$2:$C$5,3,FALSE()),""))
A209: =IF($B209="","",ROW()-1) | D209: =IF($C209="","",IFERROR(VLOOKUP($C209,Map_Register!$A$2:$C$5,3,FALSE()),""))
A210: =IF($B210="","",ROW()-1) | D210: =IF($C210="","",IFERROR(VLOOKUP($C210,Map_Register!$A$2:$C$5,3,FALSE()),""))
A211: =IF($B211="","",ROW()-1) | D211: =IF($C211="","",IFERROR(VLOOKUP($C211,Map_Register!$A$2:$C$5,3,FALSE()),""))
A212: =IF($B212="","",ROW()-1) | D212: =IF($C212="","",IFERROR(VLOOKUP($C212,Map_Register!$A$2:$C$5,3,FALSE()),""))
A213: =IF($B213="","",ROW()-1) | D213: =IF($C213="","",IFERROR(VLOOKUP($C213,Map_Register!$A$2:$C$5,3,FALSE()),""))
A214: =IF($B214="","",ROW()-1) | D214: =IF($C214="","",IFERROR(VLOOKUP($C214,Map_Register!$A$2:$C$5,3,FALSE()),""))
A215: =IF($B215="","",ROW()-1) | D215: =IF($C215="","",IFERROR(VLOOKUP($C215,Map_Register!$A$2:$C$5,3,FALSE()),""))
A216: =IF($B216="","",ROW()-1) | D216: =IF($C216="","",IFERROR(VLOOKUP($C216,Map_Register!$A$2:$C$5,3,FALSE()),""))
... A501: =IF($B501="","",ROW()-1) | D501: =IF($C501="","",IFERROR(VLOOKUP($C501,Map_Register!$A$2:$C$5,3,FALSE()),""))

Sheet Finland_Toponym
A1: Record_ID | B1: NMA | C1: Map_ID | D1: Sheet_Type | E1: Category | F1: FID | G1: Feature_Type | H1: Name(If Available) | I1: Alternative Names | J1: Languages | K1: Code | L1: RenderingStage_Flag | M1: Generalization_Flag | N1: Justification | O1: Specification_Flag | P1: Feature_Count | Q1: Bertin_Variable | R1: Reference_Source
A2: =IF($B2="","",ROW()-1) -> 1 | B2: NLS-FI | C2: NLS-FI-04 | D2: =IF($C2="","",IFERROR(VLOOKUP($C2,Map_Register!$A$2:$C$5,3,FALSE()),"")) -> Toponym Labels | E2: Toponym | F2: 700931 | G2: Lake or pond | H2: Liskujärvi | I2: Liskujärvi; Čuuskâšjävri | J2: fin;smn | K2: Present | N2: label for Lake/pond ; Finnish label on top | R2: MapSite NLS-FI
A3: =IF($B3="","",ROW()-1) -> 2 | B3: NLS-FI | C3: NLS-FI-04 | D3: =IF($C3="","",IFERROR(VLOOKUP($C3,Map_Register!$A$2:$C$5,3,FALSE()),"")) -> Toponym Labels | E3: Toponym | F3: 700932 | G3: Lake or pond | H3: Tammukkalampi | I3: Tammukkalampi; Veejeehjáávráš | J3: fin;smn | K3: Absent | L3: Yes | M3: Yes | N3: no label found; size | O3: No | R3: MapSite NLS-FI
A4: =IF($B4="","",ROW()-1) -> 3 | B4: NLS-FI | C4: NLS-FI-04 | D4: =IF($C4="","",IFERROR(VLOOKUP($C4,Map_Register!$A$2:$C$5,3,FALSE()),"")) -> Toponym Labels | E4: Toponym | F4: 700934 | G4: Lake or pond | H4: Puállámčielgijävri | I4: Puállámčielgijävri; Paloselkäjärvi | J4: smn;fin | K4: Present | N4: Finnish label on top | R4: MapSite NLS-FI
A5: =IF($B5="","",ROW()-1) -> 4 | B5: NLS-FI | C5: NLS-FI-04 | D5: =IF($C5="","",IFERROR(VLOOKUP($C5,Map_Register!$A$2:$C$5,3,FALSE()),"")) -> Toponym Labels | E5: Toponym | F5: 700951 | G5: Lake or pond | H5: Äägisvärjáávráš | I5: Äägisvärjáávráš; Hangasjärvi | J5: smn;fin | K5: Present | N5: Finnish label on top | R5: MapSite NLS-FI
A6: =IF($B6="","",ROW()-1) -> 5 | B6: NLS-FI | C6: NLS-FI-04 | D6: =IF($C6="","",IFERROR(VLOOKUP($C6,Map_Register!$A$2:$C$5,3,FALSE()),"")) -> Toponym Labels | E6: Toponym | F6: 700952 | G6: Elevation | H6: Peuranuittamaselkä | I6: Peuranuittamaselkä | J6: fin | K6: Present | N6: Label for elevation; terrain feature | R6: MapSite NLS-FI
A7: =IF($B7="","",ROW()-1) -> 6 | B7: NLS-FI | C7: NLS-FI-04 | D7: =IF($C7="","",IFERROR(VLOOKUP($C7,Map_Register!$A$2:$C$5,3,FALSE()),"")) -> Toponym Labels | E7: Toponym | F7: 700953 | G7: Elevation | H7: Pennuuvääri | I7: Pennuuvääri; Pennuuläppimvääri; Koiravaara | J7: smn;smn;fin | K7: Present | N7: Finnish in top , followed by Smn | R7: MapSite NLS-FI
A8: =IF($B8="","",ROW()-1) -> 7 | B8: NLS-FI | C8: NLS-FI-04 | D8: =IF($C8="","",IFERROR(VLOOKUP($C8,Map_Register!$A$2:$C$5,3,FALSE()),"")) -> Toponym Labels | E8: Toponym | F8: 700954 | G8: Elevation | H8: Miällááváárááš | I8: Miällááváárááš | J8: smn | K8: Present | N8: Label for elevation; terrain feature | R8: MapSite NLS-FI
A9: =IF($B9="","",ROW()-1) -> 8 | B9: NLS-FI | C9: NLS-FI-04 | D9: =IF($C9="","",IFERROR(VLOOKUP($C9,Map_Register!$A$2:$C$5,3,FALSE()),"")) -> Toponym Labels | E9: Toponym | F9: 700955 | G9: Watercourse | H9: Harrioja | I9: Harrioja; Suávviljuuvâš | J9: fin;smn | K9: Absent | L9: Yes | M9: Yes | N9: No label found in area ; size | O9: No | R9: MapSite NLS-FI
A10: =IF($B10="","",ROW()-1) -> 9 | B10: NLS-FI | C10: NLS-FI-04 | D10: =IF($C10="","",IFERROR(VLOOKUP($C10,Map_Register!$A$2:$C$5,3,FALSE()),"")) -> Toponym Labels | E10: Toponym | F10: 700956 | G10: Elevation | H10: Čapisvääri | I10: Čapisvääri; Mustavaara | J10: smn;fin | K10: Present | N10: Finnish label on top | R10: MapSite NLS-FI
A11: =IF($B11="","",ROW()-1) -> 10 | B11: NLS-FI | C11: NLS-FI-04 | D11: =IF($C11="","",IFERROR(VLOOKUP($C11,Map_Register!$A$2:$C$5,3,FALSE()),"")) -> Toponym Labels | E11: Toponym | F11: 700957 | G11: Cape | H11: Kirvesniemi | I11: Kirvesniemi; Ákšunjaargâš | J11: fin;smn | K11: Present | N11: Finnish label on top | R11: MapSite NLS-FI
A12: =IF($B12="","",ROW()-1) -> 11 | B12: NLS-FI | C12: NLS-FI-04 | D12: =IF($C12="","",IFERROR(VLOOKUP($C12,Map_Register!$A$2:$C$5,3,FALSE()),"")) -> Toponym Labels | E12: Toponym | F12: 700958 | G12: Lake or pond | H12: Lompolanjärvi | I12: Lompolanjärvi; Luobbâljävri | J12: fin;smn | K12: Present | N12: Finnish label on top | R12: MapSite NLS-FI
A13: =IF($B13="","",ROW()-1) -> 12 | B13: NLS-FI | C13: NLS-FI-04 | D13: =IF($C13="","",IFERROR(VLOOKUP($C13,Map_Register!$A$2:$C$5,3,FALSE()),"")) -> Toponym Labels | E13: Toponym | F13: 700959 | G13: Lake or pond | H13: Suávviljáávráš | I13: Suávviljáávráš; Harrijärvi | J13: smn;fin | K13: Absent | L13: Yes | M13: Yes | N13: size | O13: No | R13: MapSite NLS-FI
A14: =IF($B14="","",ROW()-1) -> 13 | B14: NLS-FI | C14: NLS-FI-04 | D14: =IF($C14="","",IFERROR(VLOOKUP($C14,Map_Register!$A$2:$C$5,3,FALSE()),"")) -> Toponym Labels | E14: Toponym | F14: 700960 | G14: Elevation | H14: Puállámčielgi | I14: Puállámčielgi; Paloselkä | J14: smn;fin | K14: Present | N14: Finnish label on top | R14: MapSite NLS-FI
A15: =IF($B15="","",ROW()-1) -> 14 | B15: NLS-FI | C15: NLS-FI-04 | D15: =IF($C15="","",IFERROR(VLOOKUP($C15,Map_Register!$A$2:$C$5,3,FALSE()),"")) -> Toponym Labels | E15: Toponym | F15: 700961 | G15: Cape | H15: Ulkuniemi | I15: Ulkuniemi; Ulgânjargâ | J15: fin;smn | K15: Present | N15: Finnish label on top | R15: MapSite NLS-FI
A16: =IF($B16="","",ROW()-1) -> 15 | B16: NLS-FI | C16: NLS-FI-04 | D16: =IF($C16="","",IFERROR(VLOOKUP($C16,Map_Register!$A$2:$C$5,3,FALSE()),"")) -> Toponym Labels | E16: Toponym | F16: 700962 | G16: Island or islet | H16: Sarmisaari | I16: Sarmisaari; Čaarmâčuážžumsuálui | J16: fin;smn | K16: Present | N16: Finnish label on top | R16: MapSite NLS-FI
A17: =IF($B17="","",ROW()-1) -> 16 | B17: NLS-FI | C17: NLS-FI-04 | D17: =IF($C17="","",IFERROR(VLOOKUP($C17,Map_Register!$A$2:$C$5,3,FALSE()),"")) -> Toponym Labels | E17: Toponym | F17: 700963 | G17: Lake or pond | H17: Uccluobbâlâš | I17: Uccluobbâlâš; Pikkulompola | J17: smn;fin | K17: Present | N17: Finnish label on top | R17: MapSite NLS-FI
A18: =IF($B18="","",ROW()-1) -> 17 | B18: NLS-FI | C18: NLS-FI-04 | D18: =IF($C18="","",IFERROR(VLOOKUP($C18,Map_Register!$A$2:$C$5,3,FALSE()),"")) -> Toponym Labels | E18: Toponym | F18: 700964 | G18: Lake or pond | H18: Misseevááráájáávráš | I18: Misseevááráájáávráš; Missevaaranjärvi | J18: smn;fin | K18: Absent | L18: Yes | M18: Yes | N18: size | O18: No | R18: MapSite NLS-FI
A19: =IF($B19="","",ROW()-1) -> 18 | B19: NLS-FI | C19: NLS-FI-04 | D19: =IF($C19="","",IFERROR(VLOOKUP($C19,Map_Register!$A$2:$C$5,3,FALSE()),"")) -> Toponym Labels | E19: Toponym | F19: 700965 | G19: Elevation | H19: Missevaara | I19: Missevaara; Misseeváárááš | J19: fin;smn | K19: Present | N19: Finnish label on top | R19: MapSite NLS-FI
A20: =IF($B20="","",ROW()-1) -> 19 | B20: NLS-FI | C20: NLS-FI-04 | D20: =IF($C20="","",IFERROR(VLOOKUP($C20,Map_Register!$A$2:$C$5,3,FALSE()),"")) -> Toponym Labels | E20: Toponym | F20: 700966 | G20: Group of lakes or ponds | H20: Mukkajärvet | I20: Mukkajärvet; Mokkejávrááh | J20: fin;smn | K20: Present | N20: Finnish label on top | R20: MapSite NLS-FI
A21: =IF($B21="","",ROW()-1) -> 20 | B21: NLS-FI | C21: NLS-FI-04 | D21: =IF($C21="","",IFERROR(VLOOKUP($C21,Map_Register!$A$2:$C$5,3,FALSE()),"")) -> Toponym Labels | E21: Toponym | F21: 700967 | G21: Lake or pond | H21: Silmäpuoliahvenjärvi | I21: Silmäpuoliahvenjärvi; Čalmepelvuáskujávrááh | J21: fin;smn | K21: Absent | L21: Yes | M21: Yes | N21: size | O21: No | R21: MapSite NLS-FI
A22: =IF($B22="","",ROW()-1) -> 21 | B22: NLS-FI | C22: NLS-FI-04 | D22: =IF($C22="","",IFERROR(VLOOKUP($C22,Map_Register!$A$2:$C$5,3,FALSE()),"")) -> Toponym Labels | E22: Toponym | F22: 700968 | G22: Group of lakes or ponds | H22: Patojärvet | I22: Patojärvet | J22: fin | K22: Present | N22: label for group of ponds | R22: MapSite NLS-FI
A23: =IF($B23="","",ROW()-1) -> 22 | B23: NLS-FI | C23: NLS-FI-04 | D23: =IF($C23="","",IFERROR(VLOOKUP($C23,Map_Register!$A$2:$C$5,3,FALSE()),"")) -> Toponym Labels | E23: Toponym | F23: 700969 | G23: Island or islet | H23: Äittilássá | I23: Äittilássá; Aittalaassa | J23: smn;fin | K23: Absent | L23: Yes | M23: Yes | N23: size | O23: No | R23: MapSite NLS-FI
A24: =IF($B24="","",ROW()-1) -> 23 | B24: NLS-FI | C24: NLS-FI-04 | D24: =IF($C24="","",IFERROR(VLOOKUP($C24,Map_Register!$A$2:$C$5,3,FALSE()),"")) -> Toponym Labels | E24: Toponym | F24: 700970 | G24: Cape | H24: Áánnášnjargâ | I24: Áánnášnjargâ | J24: smn | K24: Present | N24: Label for cape | R24: MapSite NLS-FI
A25: =IF($B25="","",ROW()-1) -> 24 | B25: NLS-FI | C25: NLS-FI-04 | D25: =IF($C25="","",IFERROR(VLOOKUP($C25,Map_Register!$A$2:$C$5,3,FALSE()),"")) -> Toponym Labels | E25: Toponym | F25: 700971 | G25: Cape | H25: Mustaniemi | I25: Mustaniemi; Čapisnjargâ | J25: fin;smn | K25: Absent | L25: Yes | M25: No | N25: no label found; enough space for label | O25: No | R25: MapSite NLS-FI
A26: =IF($B26="","",ROW()-1) -> 25 | B26: NLS-FI | C26: NLS-FI-04 | D26: =IF($C26="","",IFERROR(VLOOKUP($C26,Map_Register!$A$2:$C$5,3,FALSE()),"")) -> Toponym Labels | E26: Toponym | F26: 700972 | G26: Lake or pond | H26: Luolajärvi | I26: Luolajärvi; Juovâluovtjáávráš | J26: fin;smn | K26: Present | N26: Finnish label on top | R26: MapSite NLS-FI
A27: =IF($B27="","",ROW()-1) -> 26 | B27: NLS-FI | C27: NLS-FI-04 | D27: =IF($C27="","",IFERROR(VLOOKUP($C27,Map_Register!$A$2:$C$5,3,FALSE()),"")) -> Toponym Labels | E27: Toponym | F27: 700973 | G27: Lake or pond | H27: Pirkittajärvi | I27: Pirkittajärvi; Pirgitjáávráš | J27: fin;smn | K27: Absent | L27: Yes | M27: Yes | N27: size | O27: No | R27: MapSite NLS-FI
A28: =IF($B28="","",ROW()-1) -> 27 | B28: NLS-FI | C28: NLS-FI-04 | D28: =IF($C28="","",IFERROR(VLOOKUP($C28,Map_Register!$A$2:$C$5,3,FALSE()),"")) -> Toponym Labels | E28: Toponym | F28: 700974 | G28: Group of islands or islets | H28: Njurgomsuálui | I28: Njurgomsuálui; Vihellyssaaret | J28: smn;fin | K28: Absent | L28: Yes | M28: Yes | N28: no label found ; maybe attributable to size of island | O28: No | R28: MapSite NLS-FI
A29: =IF($B29="","",ROW()-1) -> 28 | B29: NLS-FI | C29: NLS-FI-04 | D29: =IF($C29="","",IFERROR(VLOOKUP($C29,Map_Register!$A$2:$C$5,3,FALSE()),"")) -> Toponym Labels | E29: Toponym | F29: 700975 | G29: Cape | H29: Kuávžurnjuškimnjargâ | I29: Kuávžurnjuškimnjargâ; Taimenhyppäämäniemi | J29: smn;fin | K29: Absent | L29: Yes | M29: No | N29: no label found; enough space for label | O29: No | R29: MapSite NLS-FI
A30: =IF($B30="","",ROW()-1) -> 29 | B30: NLS-FI | C30: NLS-FI-04 | D30: =IF($C30="","",IFERROR(VLOOKUP($C30,Map_Register!$A$2:$C$5,3,FALSE()),"")) -> Toponym Labels | E30: Toponym | F30: 700976 | G30: Watercourse | H30: Kähteejuuvâš | I30: Kähteejuuvâš | J30: smn | K30: Absent | L30: Yes | M30: Yes | N30: No label found in area ; size | O30: No | R30: MapSite NLS-FI
A31: =IF($B31="","",ROW()-1) -> 30 | B31: NLS-FI | C31: NLS-FI-04 | D31: =IF($C31="","",IFERROR(VLOOKUP($C31,Map_Register!$A$2:$C$5,3,FALSE()),"")) -> Toponym Labels | E31: Toponym | F31: 700977 | G31: Lake or pond | H31: Keđgivihálâh | I31: Keđgivihálâh; Kivitarpoma | J31: smn;fin | K31: Absent | L31: Yes | M31: Yes | N31: size | O31: No | R31: MapSite NLS-FI
A32: =IF($B32="","",ROW()-1) -> 31 | B32: NLS-FI | C32: NLS-FI-04 | D32: =IF($C32="","",IFERROR(VLOOKUP($C32,Map_Register!$A$2:$C$5,3,FALSE()),"")) -> Toponym Labels | E32: Toponym | F32: 700978 | G32: Cape | H32: Rissenjargâ | I32: Rissenjargâ; Vittaniemi | J32: smn;fin | K32: Present | N32: Finnish label on top | R32: MapSite NLS-FI
A33: =IF($B33="","",ROW()-1) -> 32 | B33: NLS-FI | C33: NLS-FI-04 | D33: =IF($C33="","",IFERROR(VLOOKUP($C33,Map_Register!$A$2:$C$5,3,FALSE()),"")) -> Toponym Labels | E33: Toponym | F33: 700979 | G33: Lake or pond | H33: Syeinikuovđâjáávráš | I33: Syeinikuovđâjáávráš; Heinäaronjärvi | J33: smn;fin | K33: Present | N33: Finnish label on top | R33: MapSite NLS-FI
A34: =IF($B34="","",ROW()-1) -> 33 | B34: NLS-FI | C34: NLS-FI-04 | D34: =IF($C34="","",IFERROR(VLOOKUP($C34,Map_Register!$A$2:$C$5,3,FALSE()),"")) -> Toponym Labels | E34: Toponym | F34: 700980 | G34: Elevation | H34: Kolmumkuátieennâm | I34: Kolmumkuátieennâm | J34: smn | K34: Present | N34: Label for elevation; terrain feature | R34: MapSite NLS-FI
A35: =IF($B35="","",ROW()-1) -> 34 | B35: NLS-FI | C35: NLS-FI-04 | D35: =IF($C35="","",IFERROR(VLOOKUP($C35,Map_Register!$A$2:$C$5,3,FALSE()),"")) -> Toponym Labels | E35: Toponym | F35: 700981 | G35: Watercourse | H35: Lompolanjärvenoja | I35: Lompolanjärvenoja | J35: fin | K35: Absent | L35: Yes | M35: Yes | N35: No label found in area ; small feature ;waterway symbolized | O35: No | R35: MapSite NLS-FI
A36: =IF($B36="","",ROW()-1) -> 35 | B36: NLS-FI | C36: NLS-FI-04 | D36: =IF($C36="","",IFERROR(VLOOKUP($C36,Map_Register!$A$2:$C$5,3,FALSE()),"")) -> Toponym Labels | E36: Toponym | F36: 700991 | G36: Part of lake | H36: Uusivuono | I36: Uusivuono; Uđđâvuonâ | J36: fin;smn | K36: Present | N36: Finnish label on top | R36: MapSite NLS-FI
A37: =IF($B37="","",ROW()-1) -> 36 | B37: NLS-FI | C37: NLS-FI-04 | D37: =IF($C37="","",IFERROR(VLOOKUP($C37,Map_Register!$A$2:$C$5,3,FALSE()),"")) -> Toponym Labels | E37: Toponym | F37: 700992 | G37: Part of lake | H37: Kevätkalalahti | I37: Kevätkalalahti; Kiđđâkyelluohtâ | J37: fin;smn | K37: Absent | L37: Yes | M37: Yes | N37: possible size generalization; labels nearby conflict | O37: No | R37: MapSite NLS-FI
A38: =IF($B38="","",ROW()-1) -> 37 | B38: NLS-FI | C38: NLS-FI-04 | D38: =IF($C38="","",IFERROR(VLOOKUP($C38,Map_Register!$A$2:$C$5,3,FALSE()),"")) -> Toponym Labels | E38: Toponym | F38: 700993 | G38: Part of lake | H38: Čapisluohtâ | I38: Čapisluohtâ; Mustalahti | J38: smn;fin | K38: Present | N38: Finnish label on top | R38: MapSite NLS-FI
A39: =IF($B39="","",ROW()-1) -> 38 | B39: NLS-FI | C39: NLS-FI-04 | D39: =IF($C39="","",IFERROR(VLOOKUP($C39,Map_Register!$A$2:$C$5,3,FALSE()),"")) -> Toponym Labels | E39: Toponym | F39: 700994 | G39: Rapids | H39: Läbispuálláš | I39: Läbispuálláš; Karitsaniva | J39: smn;fin | K39: Absent | L39: Yes | M39: Yes | N39: size of feature | O39: No | R39: MapSite NLS-FI
A40: =IF($B40="","",ROW()-1) -> 39 | B40: NLS-FI | C40: NLS-FI-04 | D40: =IF($C40="","",IFERROR(VLOOKUP($C40,Map_Register!$A$2:$C$5,3,FALSE()),"")) -> Toponym Labels | E40: Toponym | F40: 700995 | G40: Part of lake | H40: Annanlahti | I40: Annanlahti; Áánnášluohtâ | J40: fin;smn | K40: Absent | L40: Yes | M40: Yes | N40: possible size generalization; labels nearby conflict | O40: No | R40: MapSite NLS-FI
...

Sheet Finland_Border
A1: Record_ID | B1: NMA | C1: Map_ID | D1: Sheet_Type | E1: Category | F1: Feature_Type | G1: Name(If Available) | H1: Code | I1: RenderingStage_Flag | J1: Generalization_Flag | K1: Justification | L1: Specification_Flag | M1: Feature_Count | N1: Bertin_Variable | O1: Reference_Source
A2: =IF($B2="","",ROW()-1) -> 1 | B2: NLS-FI | C2: NLS-FI-01 | D2: =IF($C2="","",IFERROR(VLOOKUP($C2,Map_Register!$A$2:$C$5,3,FALSE()),"")) -> Border Region | E2: Border | F2: Line - International Boundary | G2: Segment 1 | H2: Present (Emphasized) | K2: National Boundary depicted by segmented dash-dot line with an added hashed buffer | M2: 1 | N2: Size and 2 color values | O2: UN Borders***; World Bank Official Borders
A3: =IF($B3="","",ROW()-1) -> 2 | B3: NLS-FI | C3: NLS-FI-01 | D3: =IF($C3="","",IFERROR(VLOOKUP($C3,Map_Register!$A$2:$C$5,3,FALSE()),"")) -> Border Region | E3: Border | F3: Line- Municipal Boundary | G3: Segment 1 | H3: Absent | I3: Yes | J3: Yes | K3: Overlaps with National Boundary, Scale specific? No | L3: No | M3: 1 | O3: MapSite NLS-FI
A4: =IF($B4="","",ROW()-1) -> 3 | B4: NLS-FI | C4: NLS-FI-01 | D4: =IF($C4="","",IFERROR(VLOOKUP($C4,Map_Register!$A$2:$C$5,3,FALSE()),"")) -> Border Region | E4: Border | F4: Line - Province | G4: Segment 1 | H4: Absent | I4: Yes | J4: Yes | K4: Overlaps with National Boundary, Scale specific? No | L4: Yes | M4: 1 | O4: MapSite NLS-FI
A5: =IF($B5="","",ROW()-1) -> 4 | B5: NLS-FI | C5: NLS-FI-01 | D5: =IF($C5="","",IFERROR(VLOOKUP($C5,Map_Register!$A$2:$C$5,3,FALSE()),"")) -> Border Region | E5: Border | F5: Line- Regional Boundary | G5: Segment 1 | H5: Absent | I5: Yes | J5: Yes | K5: Overlaps with National Boundary | L5: No | M5: 1 | O5: MapSite NLS-FI
A6: =IF($B6="","",ROW()-1) -> 5 | B6: NLS-FI | C6: NLS-FI-01 | D6: =IF($C6="","",IFERROR(VLOOKUP($C6,Map_Register!$A$2:$C$5,3,FALSE()),"")) -> Border Region | E6: Border | F6: Line - Rear boundary of boundary Zone | H6: Present | K6: Boundary depicted as a continuous hashed purple line | M6: 1 | O6: Map itself, No other reference
A7: =IF($B7="","",ROW()-1) -> 6 | B7: NLS-FI | C7: NLS-FI-01 | D7: =IF($C7="","",IFERROR(VLOOKUP($C7,Map_Register!$A$2:$C$5,3,FALSE()),"")) -> Border Region | E7: Border | F7: Line- Conservation Area | G7: Segment 1 | H7: Present | K7: rendered as conservation area boundary | M7: 1 | O7: MapSite NLS-FI
A8: =IF($B8="","",ROW()-1) -> 7 | B8: NLS-FI | C8: NLS-FI-01 | D8: =IF($C8="","",IFERROR(VLOOKUP($C8,Map_Register!$A$2:$C$5,3,FALSE()),"")) -> Border Region | E8: Border | F8: Polygon - Conservation Area | G8: Conservation Area | H8: Present | K8: rendered as an enclosed conservation area polygon | M8: 6 | O8: MapSite NLS-FI
A9: =IF($B9="","",ROW()-1) -> 8 | B9: NLS-FI | C9: NLS-FI-02 | D9: =IF($C9="","",IFERROR(VLOOKUP($C9,Map_Register!$A$2:$C$5,3,FALSE()),"")) -> Cultural Heritage Area | E9: Border | F9: Line - Limit of Territorial Waters | G9: Segment 4 | H9: Present | K9: Boundary depicted as patterned line | M9: 1 | O9: MapSite NLS-FI; Marine Regions Org
A10: =IF($B10="","",ROW()-1) -> 9 | B10: NLS-FI | C10: NLS-FI-02 | D10: =IF($C10="","",IFERROR(VLOOKUP($C10,Map_Register!$A$2:$C$5,3,FALSE()),"")) -> Cultural Heritage Area | E10: Border | F10: Line - Municipal Boundary | G10: Segment 1 | H10: Present | K10: Boundary depicted as segmented dash-dot line | M10: 1 | O10: MapSite NLS-FI
A11: =IF($B11="","",ROW()-1) -> 10 | B11: NLS-FI | C11: NLS-FI-02 | D11: =IF($C11="","",IFERROR(VLOOKUP($C11,Map_Register!$A$2:$C$5,3,FALSE()),"")) -> Cultural Heritage Area | E11: Border | F11: Line - Regional Boundary | G11: Segment 2 | H11: Present | K11: Boundary depicted as segmented dash- 2 dot line | M11: 1 | O11: MapSite NLS-FI
A12: =IF($B12="","",ROW()-1) -> 11 | B12: NLS-FI | C12: NLS-FI-02 | D12: =IF($C12="","",IFERROR(VLOOKUP($C12,Map_Register!$A$2:$C$5,3,FALSE()),"")) -> Cultural Heritage Area | E12: Border | F12: Line - Municipal Boundary | G12: Segment 3 | H12: Present | K12: Boundary depicted as segmented dash-dot line | M12: 1 | O12: MapSite NLS-FI
A13: =IF($B13="","",ROW()-1) -> 12 | B13: NLS-FI | C13: NLS-FI-02 | D13: =IF($C13="","",IFERROR(VLOOKUP($C13,Map_Register!$A$2:$C$5,3,FALSE()),"")) -> Cultural Heritage Area | E13: Border | F13: Line - Municipal Boundary | G13: Segment 2 | H13: Absent | I13: Yes | J13: Yes | K13: Overlaps with regional boundary | L13: No | M13: 1 | O13: MapSite NLS-FI
A14: =IF($B14="","",ROW()-1) -> 13 | B14: NLS-FI | C14: NLS-FI-02 | D14: =IF($C14="","",IFERROR(VLOOKUP($C14,Map_Register!$A$2:$C$5,3,FALSE()),"")) -> Cultural Heritage Area | E14: Border | F14: Line- Municipal Boundary | G14: Segment 4 | H14: Absent | I14: Yes | J14: Yes | K14: Overlaps with regional boundary | L14: No | M14: 1 | O14: MapSite NLS-FI
A15: =IF($B15="","",ROW()-1) -> 14 | B15: NLS-FI | C15: NLS-FI-02 | D15: =IF($C15="","",IFERROR(VLOOKUP($C15,Map_Register!$A$2:$C$5,3,FALSE()),"")) -> Cultural Heritage Area | E15: Border | F15: Line- Province Boundary | G15: Segment 4 | H15: Absent | I15: Yes | J15: Yes | K15: Overlaps with limit of territorial water | L15: Yes | M15: 1
A16: =IF($B16="","",ROW()-1) -> 15 | B16: NLS-FI | C16: NLS-FI-02 | D16: =IF($C16="","",IFERROR(VLOOKUP($C16,Map_Register!$A$2:$C$5,3,FALSE()),"")) -> Cultural Heritage Area | E16: Border | F16: Line- Regional Boundary | G16: Segment 4 | H16: Absent | I16: Yes | J16: Yes | K16: Overlaps with limit of territorial water | L16: No | M16: 1 | O16: MapSite NLS-FI
A17: =IF($B17="","",ROW()-1) -> 16 | B17: NLS-FI | C17: NLS-FI-02 | D17: =IF($C17="","",IFERROR(VLOOKUP($C17,Map_Register!$A$2:$C$5,3,FALSE()),"")) -> Cultural Heritage Area | E17: Border | F17: Line- Conservation Area | G17: Segment 5 | H17: Present | K17: rendered as conservation area boundary | M17: 1
A18: =IF($B18="","",ROW()-1) -> 17 | B18: NLS-FI | C18: NLS-FI-02 | D18: =IF($C18="","",IFERROR(VLOOKUP($C18,Map_Register!$A$2:$C$5,3,FALSE()),"")) -> Cultural Heritage Area | E18: Border | F18: Line- Conservation Area | G18: Segment 6 | H18: Present | K18: rendered as conservation area boundary | M18: 1
A19: =IF($B19="","",ROW()-1) -> 18 | B19: NLS-FI | C19: NLS-FI-03 | D19: =IF($C19="","",IFERROR(VLOOKUP($C19,Map_Register!$A$2:$C$5,3,FALSE()),"")) -> Military Zone | E19: Border | F19: Polygon - Conservation Area | G19: Conservation Area | H19: Present | K19: rendered as an enclosed conservation area polygon | M19: 10
A20: =IF($B20="","",ROW()-1) -> 19 | B20: NLS-FI | C20: NLS-FI-03 | D20: =IF($C20="","",IFERROR(VLOOKUP($C20,Map_Register!$A$2:$C$5,3,FALSE()),"")) -> Military Zone | E20: Border | F20: Line - Municipal Boundary | G20: Segment 1 | H20: Present | K20: Boundary depicted as segmented dash-dot line | M20: 1 | O20: MapSite NLS-FI
A21: =IF($B21="","",ROW()-1) -> 20 | B21: NLS-FI | C21: NLS-FI-03 | D21: =IF($C21="","",IFERROR(VLOOKUP($C21,Map_Register!$A$2:$C$5,3,FALSE()),"")) -> Military Zone | E21: Border | F21: Line - Municipal Boundary | G21: Segment 2 | H21: Present | K21: Boundary depicted as segmented dash-dot line | M21: 1 | O21: MapSite NLS-FI
A22: =IF($B22="","",ROW()-1) -> 21 | B22: NLS-FI | C22: NLS-FI-03 | D22: =IF($C22="","",IFERROR(VLOOKUP($C22,Map_Register!$A$2:$C$5,3,FALSE()),"")) -> Military Zone | E22: Border | F22: Line - Municipal Boundary | G22: Segment 3 | H22: Present | K22: Boundary depicted as segmented dash-dot line | M22: 1 | O22: MapSite NLS-FI
A23: =IF($B23="","",ROW()-1) -> 22 | B23: NLS-FI | C23: NLS-FI-03 | D23: =IF($C23="","",IFERROR(VLOOKUP($C23,Map_Register!$A$2:$C$5,3,FALSE()),"")) -> Military Zone | E23: Border | F23: Line-Limit of Territorial Waters | G23: Segment 5 | H23: Present | K23: Boundary symbolized as limits of territorial water , but no exising documentation that the limit of territorial waters exist there | M23: 1
A24: =IF($B24="","",ROW()-1) -> 23 | B24: NLS-FI | C24: NLS-FI-03 | D24: =IF($C24="","",IFERROR(VLOOKUP($C24,Map_Register!$A$2:$C$5,3,FALSE()),"")) -> Military Zone | E24: Border | F24: Line- Conservation Area | G24: Segment 6 | H24: Present | K24: rendered as conservation area boundary | M24: 1
A25: =IF($B25="","",ROW()-1) -> 24 | B25: NLS-FI | C25: NLS-FI-03 | D25: =IF($C25="","",IFERROR(VLOOKUP($C25,Map_Register!$A$2:$C$5,3,FALSE()),"")) -> Military Zone | E25: Border | F25: Polygon - Conservation Area | G25: Conservation Area | H25: Present | K25: rendered as an enclosed conservation area polygon | M25: 15
A26: =IF($B26="","",ROW()-1) -> 25 | B26: NLS-FI | C26: NLS-FI-04 | D26: =IF($C26="","",IFERROR(VLOOKUP($C26,Map_Register!$A$2:$C$5,3,FALSE()),"")) -> Toponym Labels | E26: Border | F26: None within sheet
A27: =IF($B27="","",ROW()-1)
A28: =IF($B28="","",ROW()-1)
A218: =IF($B218="","",ROW()-1) | D218: =IF($C218="","",IFERROR(VLOOKUP($C218,Map_Register!$A$2:$C$5,3,FALSE()),""))
A219: =IF($B219="","",ROW()-1) | D219: =IF($C219="","",IFERROR(VLOOKUP($C219,Map_Register!$A$2:$C$5,3,FALSE()),""))
A220: =IF($B220="","",ROW()-1) | D220: =IF($C220="","",IFERROR(VLOOKUP($C220,Map_Register!$A$2:$C$5,3,FALSE()),""))
A221: =IF($B221="","",ROW()-1) | D221: =IF($C221="","",IFERROR(VLOOKUP($C221,Map_Register!$A$2:$C$5,3,FALSE()),""))
A222: =IF($B222="","",ROW()-1) | D222: =IF($C222="","",IFERROR(VLOOKUP($C222,Map_Register!$A$2:$C$5,3,FALSE()),""))
A223: =IF($B223="","",ROW()-1) | D223: =IF($C223="","",IFERROR(VLOOKUP($C223,Map_Register!$A$2:$C$5,3,FALSE()),""))
A224: =IF($B224="","",ROW()-1) | D224: =IF($C224="","",IFERROR(VLOOKUP($C224,Map_Register!$A$2:$C$5,3,FALSE()),""))
A225: =IF($B225="","",ROW()-1) | D225: =IF($C225="","",IFERROR(VLOOKUP($C225,Map_Register!$A$2:$C$5,3,FALSE()),""))
A226: =IF($B226="","",ROW()-1) | D226: =IF($C226="","",IFERROR(VLOOKUP($C226,Map_Register!$A$2:$C$5,3,FALSE()),""))
A227: =IF($B227="","",ROW()-1) | D227: =IF($C227="","",IFERROR(VLOOKUP($C227,Map_Register!$A$2:$C$5,3,FALSE()),""))
A228: =IF($B228="","",ROW()-1) | D228: =IF($C228="","",IFERROR(VLOOKUP($C228,Map_Register!$A$2:$C$5,3,FALSE()),""))
A229: =IF($B229="","",ROW()-1) | D229: =IF($C229="","",IFERROR(VLOOKUP($C229,Map_Register!$A$2:$C$5,3,FALSE()),""))
...

Sheet Summary
A1: Finland Representation Inventory — Summary of Coding Results
A2: National Mapping Agency: NLS-FI | Auto-summarized from the Coding_Records sheets (Table 7 instrument, Section 3.5). Figures recalculate automatically as records are added.
A3: Note: 'Present' totals include emphasized features (Code beginning "Present"); 'Absent' totals include minor spelling/case variants (Code beginning "Absent"); 'Other/Unclear' captures any remaining codes (e.g. "outside sheet extent").
A5: 1. Overall Coding Results by Category
A6: Category | B6: Total Records | C6: Present | D6: Present (Emphasized) | E6: Absent | F6: Other / Unclear | G6: % Present | H6: % Absent
A7: Culture | B7: =COUNTA(Finland_Culture!I2:I829) -> 828 | C7: =COUNTIF(Finland_Culture!I2:I829,"Present*")-COUNTIF(Finland_Culture!I2:I829,"*Emphasi*") -> 212 | D7: =COUNTIF(Finland_Culture!I2:I829,"*Emphasi*") -> 5 | E7: =COUNTIF(Finland_Culture!I2:I829,"Absent*") -> 606 | F7: =B7-C7-D7-E7 -> 5 | G7: =IF(B7=0,0,(C7+D7)/B7) -> 0.26207729 | H7: =IF(B7=0,0,E7/B7) -> 0.73188406
A8: Border | B8: =COUNTA(Finland_Border!H2:H26) -> 24 | C8: =COUNTIF(Finland_Border!H2:H26,"Present*")-COUNTIF(Finland_Border!H2:H26,"*Emphasi*") -> 16 | D8: =COUNTIF(Finland_Border!H2:H26,"*Emphasi*") -> 1 | E8: =COUNTIF(Finland_Border!H2:H26,"Absent*") -> 7 | F8: =B8-C8-D8-E8 -> 0 | G8: =IF(B8=0,0,(C8+D8)/B8) -> 0.70833333 | H8: =IF(B8=0,0,E8/B8) -> 0.29166667
A9: Military | B9: =COUNTA(Finland_Military!H2:H2) -> 1 | C9: =COUNTIF(Finland_Military!H2:H2,"Present*")-COUNTIF(Finland_Military!H2:H2,"*Emphasi*") -> 0 | D9: =COUNTIF(Finland_Military!H2:H2,"*Emphasi*") -> 0 | E9: =COUNTIF(Finland_Military!H2:H2,"Absent*") -> 1 | F9: =B9-C9-D9-E9 -> 0 | G9: =IF(B9=0,0,(C9+D9)/B9) -> 0 | H9: =IF(B9=0,0,E9/B9) -> 1
A10: Toponym | B10: =COUNTA(Finland_Toponym!K2:K1581) -> 1580 | C10: =COUNTIF(Finland_Toponym!K2:K1581,"Present*")-COUNTIF(Finland_Toponym!K2:K1581,"*Emphasi*") -> 979 | D10: =COUNTIF(Finland_Toponym!K2:K1581,"*Emphasi*") -> 12 | E10: =COUNTIF(Finland_Toponym!K2:K1581,"Absent*") -> 589 | F10: =B10-C10-D10-E10 -> 0 | G10: =IF(B10=0,0,(C10+D10)/B10) -> 0.62721519 | H10: =IF(B10=0,0,E10/B10) -> 0.37278481
A11: TOTAL | B11: =SUM(B7:B10) -> 2433 | C11: =SUM(C7:C10) -> 1207 | D11: =SUM(D7:D10) -> 18 | E11: =SUM(E7:E10) -> 1203 | G11: =IF(B11=0,0,(C11+D11)/B11) -> 0.50349363 | H11: =IF(B11=0,0,E11/B11) -> 0.49445129
A13: 2. Visual Emphasis Analysis (share of Present features that are emphasized)
A14: Category | B14: Present (Total, incl. emphasized) | C14: Present (Emphasized) | D14: % of Present Emphasized
A15: Culture | B15: =C7+D7 -> 217 | C15: =D7 -> 5 | D15: =IF(B15=0,0,C15/B15) -> 0.023041475
A16: Border | B16: =C8+D8 -> 17 | C16: =D8 -> 1 | D16: =IF(B16=0,0,C16/B16) -> 0.058823529
A17: Military | B17: =C9+D9 -> 0 | C17: =D9 -> 0 | D17: =IF(B17=0,0,C17/B17) -> 0
A18: Toponym | B18: =C10+D10 -> 991 | C18: =D10 -> 12 | D18: =IF(B18=0,0,C18/B18) -> 0.012108981
A19: TOTAL | B19: =SUM(B15:B18) -> 1225 | C19: =SUM(C15:C18) -> 18 | D19: =IF(B19=0,0,C19/B19) -> 0.014693878
A21: 3. Absence-Reason Flag Analysis (basis coded for Absent features)
A22: Category | B22: Absent Total | C22: Rendering-Stage Omission (Yes) | D22: Specification Gap (Yes) | E22: Generalization- Attributed (Yes)
A23: Culture | B23: =E7 -> 606 | C23: =COUNTIF(Finland_Culture!J2:J829,"*Yes*") -> 606 | D23: =COUNTIF(Finland_Culture!M2:M829,"*Yes*") -> 0 | E23: =COUNTIF(Finland_Culture!K2:K829,"*Yes*") -> 605
A24: Border | B24: =E8 -> 7 | C24: =COUNTIF(Finland_Border!I2:I26,"*Yes*") -> 7 | D24: =COUNTIF(Finland_Border!L2:L26,"*Yes*") -> 2 | E24: =COUNTIF(Finland_Border!J2:J26,"*Yes*") -> 7
A25: Military | B25: =E9 -> 1 | C25: =COUNTIF(Finland_Military!I2:I2,"*Yes*") -> 0 | D25: =COUNTIF(Finland_Military!L2:L2,"*Yes*") -> 1 | E25: =COUNTIF(Finland_Military!J2:J2,"*Yes*") -> 0
A26: Toponym | B26: =E10 -> 589 | C26: =COUNTIF(Finland_Toponym!L2:L1581,"*Yes*") -> 589 | D26: =COUNTIF(Finland_Toponym!O2:O1581,"*Yes*") -> 0 | E26: =COUNTIF(Finland_Toponym!M2:M1581,"*Yes*") -> 451
A27: TOTAL | B27: =SUM(B23:B26) -> 1203 | C27: =SUM(C23:C26) -> 1202 | D27: =SUM(D23:D26) -> 3 | E27: =SUM(E23:E26) -> 1063
A29: Note: a record may carry more than one flag, so flag counts need not sum to the Absent total; N/A and blank entries are excluded from these counts.
A31: 4. Coding Coverage by Map Sample
A32: Map ID | B32: Area / Context | C32: Sheet Type | D32: Total Records | E32: Present | F32: Absent | G32: % Absent
A33: =Map_Register!A2 -> NLS-FI-01 | B33: =Map_Register!D2 -> Eastern Lapland (Russian border; close to ceded Karelian zone) | C33: =Map_Register!C2 -> Border Region | D33: =COUNTIF(Finland_Culture!$C$2:$C$829,$A33)+COUNTIF(Finland_Border!$C$2:$C$26,$A33)+COUNTIF(Finland_Military!$C$2:$C$2,$A33)+COUNTIF(Finland_Toponym!$C$2:$C$1581,$A33) -> 291 | E33: =COUNTIFS(Finland_Culture!$C$2:$C$829,$A33,Finland_Culture!$I$2:$I$829,"Present*")+COUNTIFS(Finland_Border!$C$2:$C$26,$A33,Finland_Border!$H$2:$H$26,"Present*")+COUNTIFS(Finland_Military!$C$2:$C$2,$A33,Finland_Military!$H$2:$H$2,"Present*")+COUNTIFS(Finland_Toponym!$C$2:$C$1581,$A33,Finland_Toponym!$K$2:$K$1581,"Present*") -> 217 | F33: =COUNTIFS(Finland_Culture!$C$2:$C$829,$A33,Finland_Culture!$I$2:$I$829,"Absent*")+COUNTIFS(Finland_Border!$C$2:$C$26,$A33,Finland_Border!$H$2:$H$26,"Absent*")+COUNTIFS(Finland_Military!$C$2:$C$2,$A33,Finland_Military!$H$2:$H$2,"Absent*")+COUNTIFS(Finland_Toponym!$C$2:$C$1581,$A33,Finland_Toponym!$K$2:$K$1581,"Absent*") -> 73 | G33: =IF(D33=0,0,F33/D33) -> 0.25085911
A34: =Map_Register!A3 -> NLS-FI-02 | B34: =Map_Register!D3 -> Old Rauma ( UNESCO WHS) | C34: =Map_Register!C3 -> Cultural Heritage Area | D34: =COUNTIF(Finland_Culture!$C$2:$C$829,$A34)+COUNTIF(Finland_Border!$C$2:$C$26,$A34)+COUNTIF(Finland_Military!$C$2:$C$2,$A34)+COUNTIF(Finland_Toponym!$C$2:$C$1581,$A34) -> 208 | E34: =COUNTIFS(Finland_Culture!$C$2:$C$829,$A34,Finland_Culture!$I$2:$I$829,"Present*")+COUNTIFS(Finland_Border!$C$2:$C$26,$A34,Finland_Border!$H$2:$H$26,"Present*")+COUNTIFS(Finland_Military!$C$2:$C$2,$A34,Finland_Military!$H$2:$H$2,"Present*")+COUNTIFS(Finland_Toponym!$C$2:$C$1581,$A34,Finland_Toponym!$K$2:$K$1581,"Present*") -> 104 | F34: =COUNTIFS(Finland_Culture!$C$2:$C$829,$A34,Finland_Culture!$I$2:$I$829,"Absent*")+COUNTIFS(Finland_Border!$C$2:$C$26,$A34,Finland_Border!$H$2:$H$26,"Absent*")+COUNTIFS(Finland_Military!$C$2:$C$2,$A34,Finland_Military!$H$2:$H$2,"Absent*")+COUNTIFS(Finland_Toponym!$C$2:$C$1581,$A34,Finland_Toponym!$K$2:$K$1581,"Absent*") -> 102 | G34: =IF(D34=0,0,F34/D34) -> 0.49038462
A35: =Map_Register!A4 -> NLS-FI-03 | B35: =Map_Register!D4 -> Upinniemi Naval Base | C35: =Map_Register!C4 -> Military Zone | D35: =COUNTIF(Finland_Culture!$C$2:$C$829,$A35)+COUNTIF(Finland_Border!$C$2:$C$26,$A35)+COUNTIF(Finland_Military!$C$2:$C$2,$A35)+COUNTIF(Finland_Toponym!$C$2:$C$1581,$A35) -> 696 | E35: =COUNTIFS(Finland_Culture!$C$2:$C$829,$A35,Finland_Culture!$I$2:$I$829,"Present*")+COUNTIFS(Finland_Border!$C$2:$C$26,$A35,Finland_Border!$H$2:$H$26,"Present*")+COUNTIFS(Finland_Military!$C$2:$C$2,$A35,Finland_Military!$H$2:$H$2,"Present*")+COUNTIFS(Finland_Toponym!$C$2:$C$1581,$A35,Finland_Toponym!$K$2:$K$1581,"Present*") -> 272 | F35: =COUNTIFS(Finland_Culture!$C$2:$C$829,$A35,Finland_Culture!$I$2:$I$829,"Absent*")+COUNTIFS(Finland_Border!$C$2:$C$26,$A35,Finland_Border!$H$2:$H$26,"Absent*")+COUNTIFS(Finland_Military!$C$2:$C$2,$A35,Finland_Military!$H$2:$H$2,"Absent*")+COUNTIFS(Finland_Toponym!$C$2:$C$1581,$A35,Finland_Toponym!$K$2:$K$1581,"Absent*") -> 424 | G35: =IF(D35=0,0,F35/D35) -> 0.6091954
A36: =Map_Register!A5 -> NLS-FI-04 | B36: =Map_Register!D5 -> Inari municipality | C36: =Map_Register!C5 -> Toponym Labels | D36: =COUNTIF(Finland_Culture!$C$2:$C$829,$A36)+COUNTIF(Finland_Border!$C$2:$C$26,$A36)+COUNTIF(Finland_Military!$C$2:$C$2,$A36)+COUNTIF(Finland_Toponym!$C$2:$C$1581,$A36) -> 1239 | E36: =COUNTIFS(Finland_Culture!$C$2:$C$829,$A36,Finland_Culture!$I$2:$I$829,"Present*")+COUNTIFS(Finland_Border!$C$2:$C$26,$A36,Finland_Border!$H$2:$H$26,"Present*")+COUNTIFS(Finland_Military!$C$2:$C$2,$A36,Finland_Military!$H$2:$H$2,"Present*")+COUNTIFS(Finland_Toponym!$C$2:$C$1581,$A36,Finland_Toponym!$K$2:$K$1581,"Present*") -> 632 | F36: =COUNTIFS(Finland_Culture!$C$2:$C$829,$A36,Finland_Culture!$I$2:$I$829,"Absent*")+COUNTIFS(Finland_Border!$C$2:$C$26,$A36,Finland_Border!$H$2:$H$26,"Absent*")+COUNTIFS(Finland_Military!$C$2:$C$2,$A36,Finland_Military!$H$2:$H$2,"Absent*")+COUNTIFS(Finland_Toponym!$C$2:$C$1581,$A36,Finland_Toponym!$K$2:$K$1581,"Absent*") -> 604 | G36: =IF(D36=0,0,F36/D36) -> 0.48748991
A37: TOTAL | D37: =SUM(D33:D36) -> 2434 | E37: =SUM(E33:E36) -> 1225 | F37: =SUM(F33:F36) -> 1203 | G37: =IF(D37=0,0,F37/D37) -> 0.49424815
A39: Headline Figures
A40: Total coded features (all categories) | F40: =B11 -> 2433
A41: Overall % Present (incl. emphasized) | F41: =G11 -> 0.50349363
A42: Overall % Absent | F42: =H11 -> 0.49445129
A43: Overall % of Present features visually emphasized | F43: =IF((C11+D11)=0,0,D11/(C11+D11)) -> 0.014693878

Sheet Lists
A1: NMA | B1: Category | C1: Code | D1: RenderingStage_Flag | E1: YN | F1: Bertin_Variable | G1: Sheet_Type
A2: BEV | B2: Military | C2: Absent | D2: Y | E2: Y | F2: Size | G2: Border Region
A3: NLS-FI | B3: Border | C3: Present | D3: N/A | E3: N | F3: Value | G3: Cultural Heritage Area
A4: IGN | B4: Cultural | C4: Present (Emphasized) | F4: Color | G4: Military Zone
B5: Toponym | C5: Present (De-emphasized) | F5: Typographic weight | G5: Toponym Labels
C6: Present (Differentiated) | F6: Position | G6: Control / Ordinary Area
F7: Line style
F8: N/A
