Workbook

Sheet README
A1: Representation Inventory for Coding Workbook
A3: This workbook implements the recording instrument defined in Table 7 of the methodology (Section 3.5).
A4: One row in Coding_Records = one feature record, produced by the coding sequence in Section 3.5 (omission, inclusion, visual emphasis).
A5: How to use: (1) complete Map_Register sheet numbers in Step 1.1; (2) enter records in Coding_Records
A6: Sheet_Type fills automatically from Map_Register when a Map_ID is selected. Record_ID numbers itself when NMA is entered.
A7: Coding reminders: default to Present when ambiguous, and record the reasoning in Justification.
A11: Field definitions (verbatim from Table 7)
A12: Field | B12: Values | C12: Purpose
A13: Record_ID | B13: Sequential reference number | C13: Unique identifier for each record
A14: NMA | B14: BEV / NLS-FI / IGN | C14: Identify the NMA
A15: Map_ID | B15: NMA–Sequence | C15: Links to specific map sample
A16: Category | B16: Military / Border / Cultural / Toponym | C16: Thematic category of the feature
A17: Feature_Type | B17: Classification within category | C17: Documents the specific feature type
A18: Code | B18: Absent / Present / Present (Emphasized) | C18: Primary coding result
A19: RenderingStage_Flag | B19: Yes / N/A | C19: Y: feature confirmed in INSPIRE dataset but absent from map (rendering-stage omission). N/A: INSPIRE dataset not applicable.; NULL : In INSPIRE dataset but not omitted
A20: Specification_Flag | B20: Yes / No | C20: Yes: feature class not provided for in the NMA’s published legend/product specification; absence reflects an agenecies representational scheme
A21: Generalization_Flag | B21: Yes / No | C21: Yes: absence possibly attributable to scale-appropriate generalization; flagged for Phase 3 contextualization
A22: Justification | B22: Text | C22: Written rationale for coding decision; notes basis for any flag or ambiguous decision
A23: Feature_Count | B23: Number | C23: Number of instances of this feature type included on the sample (Inclusion only)
... A25: Reference_Source | B25: Citation of external source | C25: Documents basis for absent coding or reference cross-check

Sheet Map_Register
A1: Map_ID | B1: NMA | C1: Sheet_Type | D1: Area / Context | E1: Series Sheet Number | F1: Date Published | G1: Source / URL
A2: IGN-01 | B2: IGN | C2: Border Region | D2: Campo de Gibraltar (contested international boundary) | E2: 1078 | F2: 45915 | G2: https://centrodedescargas.cnig.es/CentroDescargas/mtn50-raster
A3: IGN-02 | B3: IGN | C3: Cultural Heritage Area | D3: Sevilla region (Cathedral, Alcázar, Archivo de Indias UNESCO WHS) | E3: 984 | F3: 45915 | G3: https://centrodedescargas.cnig.es/CentroDescargas/mtn50-raster
A4: IGN-03 | B4: IGN | C4: Military Zone | D4: Cádiz, Andalusia | E4: 1061 | F4: 45915 | G4: https://centrodedescargas.cnig.es/CentroDescargas/mtn50-raster
A5: IGN-04 | B5: IGN | C5: Toponym Labels | D5: Navarra / Gipuzkoa Region | E5: 65 | F5: 45915 | G5: https://centrodedescargas.cnig.es/CentroDescargas/mtn50-raster

Sheet Spain_Border
A1: Record_ID | B1: NMA | C1: Map_ID | D1: Sheet_Type | E1: Category | F1: Feature_Type | G1: Name(If Available) | H1: Code | I1: RenderingStage_Flag | J1: Generalization_Flag | K1: Justification | L1: Specification_Flag | M1: Feature_Count | N1: Bertin_Variable | O1: Reference_Source
A2: =IF($B2="","",ROW()-1) -> 1 | B2: IGN | C2: IGN-01 | D2: =IF($C2="","",IFERROR(VLOOKUP($C2,Map_Register!$A$2:$C$5,3,FALSE()),"")) -> Border Region | E2: Border | F2: Line- Municipal Boundary | G2: Segment 1 - Muncipal | H2: Present | K2: Boundary represented as the border of a Municipality ; Boundary disputed with Britain- International boundary | O2: World Bank Official Boundaries
A3: =IF($B3="","",ROW()-1) -> 2 | B3: IGN | C3: IGN-01 | D3: =IF($C3="","",IFERROR(VLOOKUP($C3,Map_Register!$A$2:$C$5,3,FALSE()),"")) -> Border Region | E3: Border | G3: Segment 1 - Autonomous community boundary | H3: Absent | I3: Yes | J3: Yes | K3: Overlaps with Municipal boundary; municipal boundary rendered over auonomous community boundary | L3: No | O3: https://centrodedescargas.cnig.es/CentroDescargas/detalleArchivo?sec=9000029
A4: =IF($B4="","",ROW()-1) -> 3 | B4: IGN | C4: IGN-01 | D4: =IF($C4="","",IFERROR(VLOOKUP($C4,Map_Register!$A$2:$C$5,3,FALSE()),"")) -> Border Region | E4: Border | F4: Line - Province boundary | G4: Segment 1 - Province boudary | H4: Absent | I4: Yes | J4: Yes | K4: Overlaps with Municipal boundary; municipal boundary rendered over province boundary | L4: No | O4: https://centrodedescargas.cnig.es/CentroDescargas/detalleArchivo?sec=9000029
A5: =IF($B5="","",ROW()-1) -> 4 | B5: IGN | C5: IGN-01 | D5: =IF($C5="","",IFERROR(VLOOKUP($C5,Map_Register!$A$2:$C$5,3,FALSE()),"")) -> Border Region | E5: Border | F5: Line- International Boundary ; Contested/disputed boundary | G5: Segment 1 - International Boundary | H5: Absent | I5: NA | J5: Yes | K5: Boundary represented as the border of a Municipality ; Boundary disputed with Britain- International boundary ; generalization special case - active omission | L5: No | O5: https://centrodedescargas.cnig.es/CentroDescargas/detalleArchivo?sec=9000029
A6: =IF($B6="","",ROW()-1) -> 5 | B6: IGN | C6: IGN-01 | D6: =IF($C6="","",IFERROR(VLOOKUP($C6,Map_Register!$A$2:$C$5,3,FALSE()),"")) -> Border Region | E6: Border | F6: Line- Municipal Boundary | G6: Segment 2- Municipal | H6: Present | K6: municipal boundary | O6: https://centrodedescargas.cnig.es/CentroDescargas/detalleArchivo?sec=9000029
A7: =IF($B7="","",ROW()-1) -> 6 | B7: IGN | C7: IGN-01 | D7: =IF($C7="","",IFERROR(VLOOKUP($C7,Map_Register!$A$2:$C$5,3,FALSE()),"")) -> Border Region | E7: Border | F7: Line- Municipal Boundary and Natural Park and other | G7: Segment 3 -Municipal and Natural Park and other | H7: Present | K7: municipal boundary with a portion overlaping a natural park boundary , both rendered jointly just for that overlapping portion | O7: https://centrodedescargas.cnig.es/CentroDescargas/detalleArchivo?sec=9000029
A8: =IF($B8="","",ROW()-1) -> 7 | B8: IGN | C8: IGN-01 | D8: =IF($C8="","",IFERROR(VLOOKUP($C8,Map_Register!$A$2:$C$5,3,FALSE()),"")) -> Border Region | E8: Border | F8: Line- Boundary ; Contested/disputed boundary | G8: Segment 4 - Territorial Waters | H8: Absent | I8: NA | J8: No | K8: Territorial water as per UNCLOS; generalization unlikely | L8: Yes | O8: Flanders Marine Institute (2023)
A9: =IF($B9="","",ROW()-1) -> 8 | B9: IGN | C9: IGN-01 | D9: =IF($C9="","",IFERROR(VLOOKUP($C9,Map_Register!$A$2:$C$5,3,FALSE()),"")) -> Border Region | E9: Border | F9: Line- Natural Park and other | G9: Segment 5 - Natural Park and other | H9: Present (Emphasized) | K9: natural park boundary rendered as thick green segmented over blue backgorund making it very noticeable within the map sample | N9: size; bold ; hue(contrast) | O9: map itself ; OSM
A10: =IF($B10="","",ROW()-1) -> 9 | B10: IGN | C10: IGN-01 | D10: =IF($C10="","",IFERROR(VLOOKUP($C10,Map_Register!$A$2:$C$5,3,FALSE()),"")) -> Border Region | E10: Border | F10: Line- Natural Park and other | G10: Segment 6 - Natural Park and other | H10: Present | K10: rendered as natural park boundary | O10: map itself ; OSM
A11: =IF($B11="","",ROW()-1) -> 10 | B11: IGN | C11: IGN-01 | D11: =IF($C11="","",IFERROR(VLOOKUP($C11,Map_Register!$A$2:$C$5,3,FALSE()),"")) -> Border Region | E11: Border | F11: Line- Natural Park and other | G11: Segment 7 - Natural Park and other | H11: Present | K11: rendered as natural park boundary | O11: map itself ; OSM
A12: =IF($B12="","",ROW()-1) -> 11 | B12: IGN | C12: IGN-01 | D12: =IF($C12="","",IFERROR(VLOOKUP($C12,Map_Register!$A$2:$C$5,3,FALSE()),"")) -> Border Region | E12: Border | F12: Line- Natural Park and other | G12: Segment 8 - Natural Park and other | H12: Present | K12: rendered as natural park boundary | O12: map itself ; OSM
A13: =IF($B13="","",ROW()-1) -> 12 | B13: IGN | C13: IGN-03 | D13: =IF($C13="","",IFERROR(VLOOKUP($C13,Map_Register!$A$2:$C$5,3,FALSE()),"")) -> Military Zone | E13: Border | F13: Line- Municipal Boundary | G13: Segment 1- Muncipal | H13: Present | K13: municipal boundary | O13: https://centrodedescargas.cnig.es/CentroDescargas/detalleArchivo?sec=9000029
A14: =IF($B14="","",ROW()-1) -> 13 | B14: IGN | C14: IGN-03 | D14: =IF($C14="","",IFERROR(VLOOKUP($C14,Map_Register!$A$2:$C$5,3,FALSE()),"")) -> Military Zone | E14: Border | F14: Line- Municipal Boundary | G14: Segment 2- Muncipal | H14: Present | K14: municipal boundary | O14: https://centrodedescargas.cnig.es/CentroDescargas/detalleArchivo?sec=9000029
A15: =IF($B15="","",ROW()-1) -> 14 | B15: IGN | C15: IGN-03 | D15: =IF($C15="","",IFERROR(VLOOKUP($C15,Map_Register!$A$2:$C$5,3,FALSE()),"")) -> Military Zone | E15: Border | F15: Line- Municipal Boundary | G15: Segment 3- Muncipal | H15: Present | K15: municipal boundary | O15: https://centrodedescargas.cnig.es/CentroDescargas/detalleArchivo?sec=9000029
A16: =IF($B16="","",ROW()-1) -> 15 | B16: IGN | C16: IGN-03 | D16: =IF($C16="","",IFERROR(VLOOKUP($C16,Map_Register!$A$2:$C$5,3,FALSE()),"")) -> Military Zone | E16: Border | F16: Line- Municipal Boundary | G16: Segment 4- Muncipal | H16: Present | K16: municipal boundary | O16: https://centrodedescargas.cnig.es/CentroDescargas/detalleArchivo?sec=9000029
A17: =IF($B17="","",ROW()-1) -> 16 | B17: IGN | C17: IGN-03 | D17: =IF($C17="","",IFERROR(VLOOKUP($C17,Map_Register!$A$2:$C$5,3,FALSE()),"")) -> Military Zone | E17: Border | F17: Line- Natural Park and other | G17: Segment 5- Natural Park and other | H17: Present | K17: rendered as natural park boundary | O17: map itself ; OSM
A18: =IF($B18="","",ROW()-1) -> 17 | B18: IGN | C18: IGN-03 | D18: =IF($C18="","",IFERROR(VLOOKUP($C18,Map_Register!$A$2:$C$5,3,FALSE()),"")) -> Military Zone | E18: Border | F18: Line- Natural Park and other | G18: Segment 6- Natural Park and other | H18: Present | K18: rendered as natural park boundary | O18: map itself ; OSM
A19: =IF($B19="","",ROW()-1) -> 18 | B19: IGN | C19: IGN-03 | D19: =IF($C19="","",IFERROR(VLOOKUP($C19,Map_Register!$A$2:$C$5,3,FALSE()),"")) -> Military Zone | E19: Border | F19: Line- Natural Park and other | G19: Segment 7- Natural Park and other | H19: Present | K19: rendered as natural park boundary | O19: map itself ; OSM
A20: =IF($B20="","",ROW()-1) -> 19 | B20: IGN | C20: IGN-02 | D20: =IF($C20="","",IFERROR(VLOOKUP($C20,Map_Register!$A$2:$C$5,3,FALSE()),"")) -> Cultural Heritage Area | E20: Border | F20: Line- Municipal Boundary | G20: Segment 1 | H20: Present | K20: municipal boundary | O20: https://centrodedescargas.cnig.es/CentroDescargas/detalleArchivo?sec=9000029
A21: =IF($B21="","",ROW()-1) -> 20 | B21: IGN | C21: IGN-02 | D21: =IF($C21="","",IFERROR(VLOOKUP($C21,Map_Register!$A$2:$C$5,3,FALSE()),"")) -> Cultural Heritage Area | E21: Border | F21: Line- Municipal Boundary | G21: Segment 2 | H21: Present | K21: municipal boundary | O21: https://centrodedescargas.cnig.es/CentroDescargas/detalleArchivo?sec=9000029
... A41: =IF($B41="","",ROW()-1) -> 40 | B41: IGN | C41: IGN-04 | D41: =IF($C41="","",IFERROR(VLOOKUP($C41,Map_Register!$A$2:$C$5,3,FALSE()),"")) -> Toponym Labels | E41: Border | F41: Line- International Boundary | G41: Segment 1- International Boundary | H41: Present | K41: International boundary with France -Nacion; Province,Autonomous community and municipal boundary also present but not rendered. Only the International boundary is rendered | O41: World Bank Official Boundaries
A42: =IF($B42="","",ROW()-1) -> 41 | B42: IGN | C42: IGN-04 | D42: =IF($C42="","",IFERROR(VLOOKUP($C42,Map_Register!$A$2:$C$5,3,FALSE()),"")) -> Toponym Labels | E42: Border | F42: Line- Autonomous Community Boundary | G42: Segment 1- Autonomous Community boundary | H42: Absent | I42: Yes | J42: Yes | K42: overlap with international boundary | L42: No | O42: https://centrodedescargas.cnig.es/CentroDescargas/detalleArchivo?sec=9000029
A43: =IF($B43="","",ROW()-1) -> 42 | B43: IGN | C43: IGN-04 | D43: =IF($C43="","",IFERROR(VLOOKUP($C43,Map_Register!$A$2:$C$5,3,FALSE()),"")) -> Toponym Labels | E43: Border | F43: Line- Province Boundary | G43: Segment 1- Province boundary | H43: Absent | I43: Yes | J43: Yes | K43: overlap with international boundary | L43: No | O43: https://centrodedescargas.cnig.es/CentroDescargas/detalleArchivo?sec=9000029
A44: =IF($B44="","",ROW()-1) -> 43 | B44: IGN | C44: IGN-04 | D44: =IF($C44="","",IFERROR(VLOOKUP($C44,Map_Register!$A$2:$C$5,3,FALSE()),"")) -> Toponym Labels | E44: Border | F44: Line- Municipal Boundary | G44: Segment 1- Municipal Boundary | H44: Absent | I44: Yes | J44: Yes | K44: overlap with international boundary | L44: No | O44: https://centrodedescargas.cnig.es/CentroDescargas/detalleArchivo?sec=9000029
A45: =IF($B45="","",ROW()-1) -> 44 | B45: IGN | C45: IGN-04 | D45: =IF($C45="","",IFERROR(VLOOKUP($C45,Map_Register!$A$2:$C$5,3,FALSE()),"")) -> Toponym Labels | E45: Border | F45: Line- Autonomous Community Boundary | G45: Segment 2 - Autonomous Community and Natural Park and other | H45: Present | K45: Autonomous Community boundary rendered. Overlap with province boundaries and municipal but only Autonomous Community boundary is rendered.jointly with natural park boundary | O45: https://centrodedescargas.cnig.es/CentroDescargas/detalleArchivo?sec=9000029
A46: =IF($B46="","",ROW()-1) -> 45 | B46: IGN | C46: IGN-04 | D46: =IF($C46="","",IFERROR(VLOOKUP($C46,Map_Register!$A$2:$C$5,3,FALSE()),"")) -> Toponym Labels | E46: Border | F46: Line- Municipal Boundary | G46: Segment 3 -Municipal Boundary | H46: Present | K46: municipal boundary | O46: https://centrodedescargas.cnig.es/CentroDescargas/detalleArchivo?sec=9000029
A47: =IF($B47="","",ROW()-1) -> 46 | B47: IGN | C47: IGN-04 | D47: =IF($C47="","",IFERROR(VLOOKUP($C47,Map_Register!$A$2:$C$5,3,FALSE()),"")) -> Toponym Labels | E47: Border | F47: Line- Municipal Boundary | G47: Segment 4 - Municipal Boundary | H47: Present | K47: municipal boundary | O47: https://centrodedescargas.cnig.es/CentroDescargas/detalleArchivo?sec=9000029
A48: =IF($B48="","",ROW()-1) -> 47 | B48: IGN | C48: IGN-04 | D48: =IF($C48="","",IFERROR(VLOOKUP($C48,Map_Register!$A$2:$C$5,3,FALSE()),"")) -> Toponym Labels | E48: Border | F48: Line- Municipal Boundary | G48: Segment 5 - Municipal Boundary | H48: Present | K48: municipal boundary | O48: https://centrodedescargas.cnig.es/CentroDescargas/detalleArchivo?sec=9000029
A49: =IF($B49="","",ROW()-1) -> 48 | B49: IGN | C49: IGN-04 | D49: =IF($C49="","",IFERROR(VLOOKUP($C49,Map_Register!$A$2:$C$5,3,FALSE()),"")) -> Toponym Labels | E49: Border | F49: Line- Municipal Boundary | G49: Segment 6 - Municipal Boundary | H49: Present | K49: municipal boundary | O49: https://centrodedescargas.cnig.es/CentroDescargas/detalleArchivo?sec=9000029
A50: =IF($B50="","",ROW()-1) -> 49 | B50: IGN | C50: IGN-04 | D50: =IF($C50="","",IFERROR(VLOOKUP($C50,Map_Register!$A$2:$C$5,3,FALSE()),"")) -> Toponym Labels | E50: Border | F50: Line- Municipal Boundary | G50: Segment 7 - Municipal Boundary | H50: Present | K50: municipal boundary | O50: https://centrodedescargas.cnig.es/CentroDescargas/detalleArchivo?sec=9000029
A51: =IF($B51="","",ROW()-1) -> 50 | B51: IGN | C51: IGN-04 | D51: =IF($C51="","",IFERROR(VLOOKUP($C51,Map_Register!$A$2:$C$5,3,FALSE()),"")) -> Toponym Labels | E51: Border | F51: Line- Municipal Boundary | G51: Segment 8 - Municipal Boundary | H51: Present | K51: municipal boundary | O51: https://centrodedescargas.cnig.es/CentroDescargas/detalleArchivo?sec=9000029
A52: =IF($B52="","",ROW()-1) -> 51 | B52: IGN | C52: IGN-04 | D52: =IF($C52="","",IFERROR(VLOOKUP($C52,Map_Register!$A$2:$C$5,3,FALSE()),"")) -> Toponym Labels | E52: Border | F52: Line- Municipal Boundary | G52: Segment 9 - Municipal Boundary | H52: Present | K52: municipal boundary | O52: https://centrodedescargas.cnig.es/CentroDescargas/detalleArchivo?sec=9000029
A53: =IF($B53="","",ROW()-1) -> 52 | B53: IGN | C53: IGN-04 | D53: =IF($C53="","",IFERROR(VLOOKUP($C53,Map_Register!$A$2:$C$5,3,FALSE()),"")) -> Toponym Labels | E53: Border | F53: Line- Municipal Boundary | G53: Segment 10 - Municipal Boundary | H53: Present | K53: municipal boundary | O53: https://centrodedescargas.cnig.es/CentroDescargas/detalleArchivo?sec=9000029
A54: =IF($B54="","",ROW()-1) -> 53 | B54: IGN | C54: IGN-04 | D54: =IF($C54="","",IFERROR(VLOOKUP($C54,Map_Register!$A$2:$C$5,3,FALSE()),"")) -> Toponym Labels | E54: Border | F54: Line- Municipal Boundary | G54: Segment 11 - Municipal Boundary | H54: Present | K54: municipal boundary | O54: https://centrodedescargas.cnig.es/CentroDescargas/detalleArchivo?sec=9000029
A55: =IF($B55="","",ROW()-1) -> 54 | B55: IGN | C55: IGN-04 | D55: =IF($C55="","",IFERROR(VLOOKUP($C55,Map_Register!$A$2:$C$5,3,FALSE()),"")) -> Toponym Labels | E55: Border | F55: Line- Municipal Boundary | G55: Segment 12 - Municipal Boundary | H55: Present | K55: municipal boundary | O55: https://centrodedescargas.cnig.es/CentroDescargas/detalleArchivo?sec=9000029
A56: =IF($B56="","",ROW()-1) -> 55 | B56: IGN | C56: IGN-04 | D56: =IF($C56="","",IFERROR(VLOOKUP($C56,Map_Register!$A$2:$C$5,3,FALSE()),"")) -> Toponym Labels | E56: Border | F56: Line- Municipal Boundary | G56: Segment 13 -Municipal Boundary | H56: Present | K56: municipal boundary | O56: https://centrodedescargas.cnig.es/CentroDescargas/detalleArchivo?sec=9000029
... A61: =IF($B61="","",ROW()-1) -> 60 | B61: IGN | C61: IGN-04 | D61: =IF($C61="","",IFERROR(VLOOKUP($C61,Map_Register!$A$2:$C$5,3,FALSE()),"")) -> Toponym Labels | E61: Border | F61: Line- Natural Park and other | G61: Segment 19- Natural Park and other | H61: Present | K61: rendered as natural park boundary; overlaps a portion of segment 1 where international boundary is rendered. | O61: map itself ; OSM
A222: =IF($B222="","",ROW()-1) | D222: =IF($C222="","",IFERROR(VLOOKUP($C222,Map_Register!$A$2:$C$5,3,FALSE()),""))
A223: =IF($B223="","",ROW()-1) | D223: =IF($C223="","",IFERROR(VLOOKUP($C223,Map_Register!$A$2:$C$5,3,FALSE()),""))
...

Sheet Spain_Military
A1: Record_ID | B1: NMA | C1: Map_ID | D1: Sheet_Type | E1: Category | F1: Feature_Type | G1: Name(If Available) | H1: Code | I1: RenderingStage_Flag | J1: Generalization_Flag | K1: Justification | L1: Specification_Flag | M1: Feature_Count | N1: Bertin_Variable | O1: Reference_Source
A2: =IF($B2="","",ROW()-1) -> 1 | B2: IGN | C2: IGN-03 | D2: =IF($C2="","",IFERROR(VLOOKUP($C2,Map_Register!$A$2:$C$5,3,FALSE()),"")) -> Military Zone | E2: Military | F2: Restricted area polygon | G2: Base Naval Aerodromo de Cadis / Rota | H2: Absent | I2: NA | J2: No | K2: No indication of restricted area or military use | L2: Yes | O2: https://armada.defensa.gob.es/ArmadaPortal/page/Portal/ArmadaEspannola/conocenosorganizacion/prefLang-es/04Apoyofuerza--02jal--05Arsenales--01arsenalcadiz ; OSM
A3: =IF($B3="","",ROW()-1) -> 2 | B3: IGN | C3: IGN-03 | D3: =IF($C3="","",IFERROR(VLOOKUP($C3,Map_Register!$A$2:$C$5,3,FALSE()),"")) -> Military Zone | E3: Military | F3: Label | G3: Puerto de la Base Aeronaval de la Rota | H3: Present | K3: Label of Aero-Naval base in Rota; Under local authoritaties label | O3: Map itself
A4: =IF($B4="","",ROW()-1) -> 3 | B4: IGN | C4: IGN-03 | D4: =IF($C4="","",IFERROR(VLOOKUP($C4,Map_Register!$A$2:$C$5,3,FALSE()),"")) -> Military Zone | E4: Military | F4: Label | G4: Base Naval Aerodromo de Cadiz / Rota | H4: Present | K4: Label of Naval Base in Cadiz / Rota; Under local authorities label | O4: Map itself
A5: =IF($B5="","",ROW()-1) -> 4 | B5: IGN | C5: IGN-01 | D5: =IF($C5="","",IFERROR(VLOOKUP($C5,Map_Register!$A$2:$C$5,3,FALSE()),"")) -> Border Region | E5: Military | F5: Label | G5: Base Naval de Gibraltar | H5: Present | K5: Label of Naval Base in Gibraltar | O5: Map itself
A6: =IF($B6="","",ROW()-1) -> 5 | B6: IGN | C6: IGN-01 | D6: =IF($C6="","",IFERROR(VLOOKUP($C6,Map_Register!$A$2:$C$5,3,FALSE()),"")) -> Border Region | E6: Military | F6: Label | G6: Acuartelameineto Adalides | H6: Present | K6: Label of Barracks | O6: https://www.boe.es/diario_boe/txt.php?id=BOE-A-1998-17931
A7: =IF($B7="","",ROW()-1) -> 6 | B7: IGN | C7: IGN-01 | D7: =IF($C7="","",IFERROR(VLOOKUP($C7,Map_Register!$A$2:$C$5,3,FALSE()),"")) -> Border Region | E7: Military | F7: Restricted area polygon | G7: HM Naval Base Gibraltar | H7: Absent | I7: NA | J7: No | K7: No indication of restricted area or military use | L7: Yes | O7: https://www.gov.uk/ ; OSM
A8: =IF($B8="","",ROW()-1) -> 7 | B8: IGN | C8: IGN-02 | D8: =IF($C8="","",IFERROR(VLOOKUP($C8,Map_Register!$A$2:$C$5,3,FALSE()),"")) -> Cultural Heritage Area | E8: Military | F8: Military Headquarters | G8: Cuartel General de la Fuerza Terrestre | H8: Present | K8: Singular building with label "Antigua Capitania General " | O8: https://ejercito.defensa.gob.es/unidades/Sevilla/futer/ ; OSM
A9: =IF($B9="","",ROW()-1) -> 8 | B9: IGN | C9: IGN-02 | D9: =IF($C9="","",IFERROR(VLOOKUP($C9,Map_Register!$A$2:$C$5,3,FALSE()),"")) -> Cultural Heritage Area | E9: Military | F9: Military Barracks | G9: Acuartelamiento La Borbolla | H9: Absent | I9: NA | J9: No | K9: No indication of restricted area or military use | L9: Yes | O9: https://ejercito.defensa.gob.es/unidades/Sevilla/suigesur/Localizacion/index.html ; OSM
D10: =IF($C10="","",IFERROR(VLOOKUP($C10,Map_Register!$A$2:$C$5,3,FALSE()),""))
D11: =IF($C11="","",IFERROR(VLOOKUP($C11,Map_Register!$A$2:$C$5,3,FALSE()),""))
D12: =IF($C12="","",IFERROR(VLOOKUP($C12,Map_Register!$A$2:$C$5,3,FALSE()),""))
D13: =IF($C13="","",IFERROR(VLOOKUP($C13,Map_Register!$A$2:$C$5,3,FALSE()),""))
D14: =IF($C14="","",IFERROR(VLOOKUP($C14,Map_Register!$A$2:$C$5,3,FALSE()),""))
D15: =IF($C15="","",IFERROR(VLOOKUP($C15,Map_Register!$A$2:$C$5,3,FALSE()),""))
D16: =IF($C16="","",IFERROR(VLOOKUP($C16,Map_Register!$A$2:$C$5,3,FALSE()),""))
D17: =IF($C17="","",IFERROR(VLOOKUP($C17,Map_Register!$A$2:$C$5,3,FALSE()),""))
D18: =IF($C18="","",IFERROR(VLOOKUP($C18,Map_Register!$A$2:$C$5,3,FALSE()),""))
D19: =IF($C19="","",IFERROR(VLOOKUP($C19,Map_Register!$A$2:$C$5,3,FALSE()),""))
D20: =IF($C20="","",IFERROR(VLOOKUP($C20,Map_Register!$A$2:$C$5,3,FALSE()),""))
D21: =IF($C21="","",IFERROR(VLOOKUP($C21,Map_Register!$A$2:$C$5,3,FALSE()),""))
... D26: =IF($C26="","",IFERROR(VLOOKUP($C26,Map_Register!$A$2:$C$5,3,FALSE()),""))
A208: =IF($B208="","",ROW()-1) | D208: =IF($C208="","",IFERROR(VLOOKUP($C208,Map_Register!$A$2:$C$5,3,FALSE()),""))
A209: =IF($B209="","",ROW()-1) | D209: =IF($C209="","",IFERROR(VLOOKUP($C209,Map_Register!$A$2:$C$5,3,FALSE()),""))
A210: =IF($B210="","",ROW()-1) | D210: =IF($C210="","",IFERROR(VLOOKUP($C210,Map_Register!$A$2:$C$5,3,FALSE()),""))
A211: =IF($B211="","",ROW()-1) | D211: =IF($C211="","",IFERROR(VLOOKUP($C211,Map_Register!$A$2:$C$5,3,FALSE()),""))
A212: =IF($B212="","",ROW()-1) | D212: =IF($C212="","",IFERROR(VLOOKUP($C212,Map_Register!$A$2:$C$5,3,FALSE()),""))
A213: =IF($B213="","",ROW()-1) | D213: =IF($C213="","",IFERROR(VLOOKUP($C213,Map_Register!$A$2:$C$5,3,FALSE()),""))
A214: =IF($B214="","",ROW()-1) | D214: =IF($C214="","",IFERROR(VLOOKUP($C214,Map_Register!$A$2:$C$5,3,FALSE()),""))
A215: =IF($B215="","",ROW()-1) | D215: =IF($C215="","",IFERROR(VLOOKUP($C215,Map_Register!$A$2:$C$5,3,FALSE()),""))
A216: =IF($B216="","",ROW()-1) | D216: =IF($C216="","",IFERROR(VLOOKUP($C216,Map_Register!$A$2:$C$5,3,FALSE()),""))
A217: =IF($B217="","",ROW()-1) | D217: =IF($C217="","",IFERROR(VLOOKUP($C217,Map_Register!$A$2:$C$5,3,FALSE()),""))
A218: =IF($B218="","",ROW()-1) | D218: =IF($C218="","",IFERROR(VLOOKUP($C218,Map_Register!$A$2:$C$5,3,FALSE()),""))
A219: =IF($B219="","",ROW()-1) | D219: =IF($C219="","",IFERROR(VLOOKUP($C219,Map_Register!$A$2:$C$5,3,FALSE()),""))
... A504: =IF($B504="","",ROW()-1) | D504: =IF($C504="","",IFERROR(VLOOKUP($C504,Map_Register!$A$2:$C$5,3,FALSE()),""))

Sheet Spain_Toponym
A1: Record_ID | B1: NMA | C1: Map_ID | D1: Sheet_Type | E1: Category | F1: FID | G1: Feature_Type | H1: Name(If Available) | I1: Languages | J1: Code | K1: RenderingStage_Flag | L1: Generalization_Flag | M1: Justification | N1: Specification_Flag | O1: Feature_Count | P1: Bertin_Variable | Q1: Reference_Source
A2: =IF($B2="","",ROW()-1) -> 1 | B2: IGN | C2: IGN-04 | D2: =IF($C2="","",IFERROR(VLOOKUP($C2,Map_Register!$A$2:$C$5,3,FALSE()),"")) -> Toponym Labels | E2: Toponym | F2: 46 | G2: Park | H2: Parque Natural Señorío de Bertiz | I2: Spanish | J2: Present (Emphasized) | M2: all caps; size of letter | Q2: https://centrodedescargas.cnig.es/CentroDescargas/btn-poi
A3: =IF($B3="","",ROW()-1) -> 2 | B3: IGN | C3: IGN-04 | D3: =IF($C3="","",IFERROR(VLOOKUP($C3,Map_Register!$A$2:$C$5,3,FALSE()),"")) -> Toponym Labels | E3: Toponym | F3: 177 | G3: Natural Reserve | H3: Reserva Natural San Juan Xar | I3: Spanish | J3: Absent | K3: Yes | L3: Yes | M3: No label found; limited space for label and other labels nearby | N3: No | Q3: https://centrodedescargas.cnig.es/CentroDescargas/btn-poi
A4: =IF($B4="","",ROW()-1) -> 3 | B4: IGN | C4: IGN-04 | D4: =IF($C4="","",IFERROR(VLOOKUP($C4,Map_Register!$A$2:$C$5,3,FALSE()),"")) -> Toponym Labels | E4: Toponym | F4: 216 | G4: Natural Reserve | H4: Reserva Natural Labiaga | I4: Spanish | J4: Present | M4: only Labeaga | Q4: https://centrodedescargas.cnig.es/CentroDescargas/btn-poi
A5: =IF($B5="","",ROW()-1) -> 4 | B5: IGN | C5: IGN-04 | D5: =IF($C5="","",IFERROR(VLOOKUP($C5,Map_Register!$A$2:$C$5,3,FALSE()),"")) -> Toponym Labels | E5: Toponym | F5: 323 | G5: Natural Monument | H5: Monumento Natural Tejo de Etxalar | I5: Spanish | J5: Present | M5: another similar label | Q5: https://centrodedescargas.cnig.es/CentroDescargas/btn-poi
A6: =IF($B6="","",ROW()-1) -> 5 | B6: IGN | C6: IGN-04 | D6: =IF($C6="","",IFERROR(VLOOKUP($C6,Map_Register!$A$2:$C$5,3,FALSE()),"")) -> Toponym Labels | E6: Toponym | F6: 378 | G6: Natural Monument | H6: Monumento Natural Acebo de Bera | I6: Spanish | J6: Present | M6: Acebo de Bera | Q6: https://centrodedescargas.cnig.es/CentroDescargas/btn-poi
A7: =IF($B7="","",ROW()-1) -> 6 | B7: IGN | C7: IGN-04 | D7: =IF($C7="","",IFERROR(VLOOKUP($C7,Map_Register!$A$2:$C$5,3,FALSE()),"")) -> Toponym Labels | E7: Toponym | F7: 396 | G7: Natural Monument | H7: Monumento Natural Peral de Bera | I7: Spanish | J7: Present | M7: Peral de Bera/ Berako Udareondoa ; separated by slash | Q7: https://centrodedescargas.cnig.es/CentroDescargas/btn-poi
A8: =IF($B8="","",ROW()-1) -> 7 | B8: IGN | C8: IGN-04 | D8: =IF($C8="","",IFERROR(VLOOKUP($C8,Map_Register!$A$2:$C$5,3,FALSE()),"")) -> Toponym Labels | E8: Toponym | F8: 436 | G8: Natural Monument | H8: Monumento Natural Sequoya del Embalse de Domiko | I8: Spanish | J8: Present | M8: similar label | Q8: https://centrodedescargas.cnig.es/CentroDescargas/btn-poi
A9: =IF($B9="","",ROW()-1) -> 8 | B9: IGN | C9: IGN-04 | D9: =IF($C9="","",IFERROR(VLOOKUP($C9,Map_Register!$A$2:$C$5,3,FALSE()),"")) -> Toponym Labels | E9: Toponym | F9: 1020 | G9: Tree | H9: Acebo de Bera/Berako gorostia | I9: Basque | J9: Present | M9: Both labels present ; slash seprated ; equal visual weight; individual tree | Q9: https://centrodedescargas.cnig.es/CentroDescargas/btn-poi
A10: =IF($B10="","",ROW()-1) -> 9 | B10: IGN | C10: IGN-04 | D10: =IF($C10="","",IFERROR(VLOOKUP($C10,Map_Register!$A$2:$C$5,3,FALSE()),"")) -> Toponym Labels | E10: Toponym | F10: 1022 | G10: Tree | H10: Peral de Bera/Berako udareondoa | I10: Basque | J10: Present | M10: as Peral de Bera ; sett name? | Q10: https://centrodedescargas.cnig.es/CentroDescargas/btn-poi
A11: =IF($B11="","",ROW()-1) -> 10 | B11: IGN | C11: IGN-04 | D11: =IF($C11="","",IFERROR(VLOOKUP($C11,Map_Register!$A$2:$C$5,3,FALSE()),"")) -> Toponym Labels | E11: Toponym | F11: 1036 | G11: Tree | H11: Sequoya del Embalse de Domiko/Domikoko Urtegiko sekuoia | I11: Basque | J11: Present | M11: both names appear separated by / | Q11: https://centrodedescargas.cnig.es/CentroDescargas/btn-poi
A12: =IF($B12="","",ROW()-1) -> 11 | B12: IGN | C12: IGN-04 | D12: =IF($C12="","",IFERROR(VLOOKUP($C12,Map_Register!$A$2:$C$5,3,FALSE()),"")) -> Toponym Labels | E12: Toponym | F12: 1037 | G12: Tree | H12: Tejo de Etxalar/Etxalarko hagina | I12: Basque | J12: Present | M12: label styled as Tree | Q12: https://centrodedescargas.cnig.es/CentroDescargas/btn-poi
A13: =IF($B13="","",ROW()-1) -> 12 | B13: IGN | C13: IGN-04 | D13: =IF($C13="","",IFERROR(VLOOKUP($C13,Map_Register!$A$2:$C$5,3,FALSE()),"")) -> Toponym Labels | E13: Toponym | F13: 3152 | G13: Natural Cave | H13: Cuevas de Zugarramurdi | I13: Spanish | J13: Absent | K13: Yes | L13: Yes | M13: No label found; limited space for label and other labels nearby | N13: No | Q13: https://centrodedescargas.cnig.es/CentroDescargas/btn-poi
A14: =IF($B14="","",ROW()-1) -> 13 | B14: IGN | C14: IGN-04 | D14: =IF($C14="","",IFERROR(VLOOKUP($C14,Map_Register!$A$2:$C$5,3,FALSE()),"")) -> Toponym Labels | E14: Toponym | F14: 3771 | G14: Natural Cave | H14: Gruta de San Juan Xarr | I14: Spanish | J14: Absent | K14: Yes | L14: Yes | M14: No label found; limited space for label and other labels nearby | N14: No | Q14: https://centrodedescargas.cnig.es/CentroDescargas/btn-poi
A15: =IF($B15="","",ROW()-1) -> 14 | B15: IGN | C15: IGN-04 | D15: =IF($C15="","",IFERROR(VLOOKUP($C15,Map_Register!$A$2:$C$5,3,FALSE()),"")) -> Toponym Labels | E15: Toponym | F15: 4126 | G15: Natural Cave | H15: Gruta de la Bruja | I15: Spanish | J15: Absent | K15: Yes | L15: Yes | M15: No label found; limited space for label and other labels nearby | N15: No | Q15: https://centrodedescargas.cnig.es/CentroDescargas/btn-poi
A16: =IF($B16="","",ROW()-1) -> 15 | B16: IGN | C16: IGN-04 | D16: =IF($C16="","",IFERROR(VLOOKUP($C16,Map_Register!$A$2:$C$5,3,FALSE()),"")) -> Toponym Labels | E16: Toponym | F16: 5088 | G16: Short-Distance Trail | H16: PR-GI-1007 (Antigua Via Férrea de Artikutza) | I16: Spanish | J16: Absent | K16: Yes | L16: Yes | M16: No label found; limited space for label and other labels nearby | N16: No | Q16: https://centrodedescargas.cnig.es/CentroDescargas/btn-poi
A17: =IF($B17="","",ROW()-1) -> 16 | B17: IGN | C17: IGN-04 | D17: =IF($C17="","",IFERROR(VLOOKUP($C17,Map_Register!$A$2:$C$5,3,FALSE()),"")) -> Toponym Labels | E17: Toponym | F17: 8156 | G17: Other routes | H17: SL-GI 1006 (Cascada de Aitzondo) | I17: Spanish | J17: Absent | K17: Yes | L17: Yes | M17: No label found; limited space for label and other labels nearby | N17: No | Q17: https://centrodedescargas.cnig.es/CentroDescargas/btn-poi
A18: =IF($B18="","",ROW()-1) -> 17 | B18: IGN | C18: IGN-04 | D18: =IF($C18="","",IFERROR(VLOOKUP($C18,Map_Register!$A$2:$C$5,3,FALSE()),"")) -> Toponym Labels | E18: Toponym | F18: 8388 | G18: Long-Distance Trail | H18: GR 11 (Etapa 02. Bera-Elizondo) | I18: Spanish | J18: Absent | K18: Yes | L18: Yes | M18: road? | N18: No | Q18: https://centrodedescargas.cnig.es/CentroDescargas/btn-poi
A19: =IF($B19="","",ROW()-1) -> 18 | B19: IGN | C19: IGN-04 | D19: =IF($C19="","",IFERROR(VLOOKUP($C19,Map_Register!$A$2:$C$5,3,FALSE()),"")) -> Toponym Labels | E19: Toponym | F19: 16969 | G19: Region | H19: Montes de Bidasoa | I19: Spanish | J19: Present | M19: Label styled as region | Q19: https://centrodedescargas.cnig.es/CentroDescargas/btn-poi
A20: =IF($B20="","",ROW()-1) -> 19 | B20: IGN | C20: IGN-04 | D20: =IF($C20="","",IFERROR(VLOOKUP($C20,Map_Register!$A$2:$C$5,3,FALSE()),"")) -> Toponym Labels | E20: Toponym | F20: 102008 | G20: Landscape | H20: Orozko-Zubieta | I20: Basque | J20: Present | M20: labelled as landscape | Q20: https://centrodedescargas.cnig.es/CentroDescargas/btn-poi
A21: =IF($B21="","",ROW()-1) -> 20 | B21: IGN | C21: IGN-04 | D21: =IF($C21="","",IFERROR(VLOOKUP($C21,Map_Register!$A$2:$C$5,3,FALSE()),"")) -> Toponym Labels | E21: Toponym | F21: 102009 | G21: Landscape | H21: Guruspil | I21: Basque | J21: Absent | K21: Yes | L21: No | M21: Label not found; enough space for label; generalization is unlikely- space for label is available | N21: No | Q21: https://centrodedescargas.cnig.es/CentroDescargas/btn-poi
A22: =IF($B22="","",ROW()-1) -> 21 | B22: IGN | C22: IGN-04 | D22: =IF($C22="","",IFERROR(VLOOKUP($C22,Map_Register!$A$2:$C$5,3,FALSE()),"")) -> Toponym Labels | E22: Toponym | F22: 102010 | G22: Landscape | H22: Cantera de Idiburuta | I22: Basque | J22: Present | M22: labelled as landscape | Q22: https://centrodedescargas.cnig.es/CentroDescargas/btn-poi
A23: =IF($B23="","",ROW()-1) -> 22 | B23: IGN | C23: IGN-04 | D23: =IF($C23="","",IFERROR(VLOOKUP($C23,Map_Register!$A$2:$C$5,3,FALSE()),"")) -> Toponym Labels | E23: Toponym | F23: 102011 | G23: Landscape | H23: Gogorregia | I23: Basque | J23: Absent | K23: Yes | L23: No | M23: Label not found; enough space for label; generalization is unlikely- space for label is available | N23: No | Q23: https://centrodedescargas.cnig.es/CentroDescargas/btn-poi
A24: =IF($B24="","",ROW()-1) -> 23 | B24: IGN | C24: IGN-04 | D24: =IF($C24="","",IFERROR(VLOOKUP($C24,Map_Register!$A$2:$C$5,3,FALSE()),"")) -> Toponym Labels | E24: Toponym | F24: 102012 | G24: Landscape | H24: Loma de Alegi | I24: Basque | J24: Present | M24: labelled as landscape | Q24: https://centrodedescargas.cnig.es/CentroDescargas/btn-poi
A25: =IF($B25="","",ROW()-1) -> 24 | B25: IGN | C25: IGN-04 | D25: =IF($C25="","",IFERROR(VLOOKUP($C25,Map_Register!$A$2:$C$5,3,FALSE()),"")) -> Toponym Labels | E25: Toponym | F25: 102013 | G25: Landscape | H25: Loma de Elutxea | I25: Basque | J25: Present | M25: labelled as landscape | Q25: https://centrodedescargas.cnig.es/CentroDescargas/btn-poi
A26: =IF($B26="","",ROW()-1) -> 25 | B26: IGN | C26: IGN-04 | D26: =IF($C26="","",IFERROR(VLOOKUP($C26,Map_Register!$A$2:$C$5,3,FALSE()),"")) -> Toponym Labels | E26: Toponym | F26: 102014 | G26: Landscape | H26: Amekurrun | I26: Basque | J26: Present | M26: labelled as landscape | Q26: https://centrodedescargas.cnig.es/CentroDescargas/btn-poi
A27: =IF($B27="","",ROW()-1) -> 26 | B27: IGN | C27: IGN-04 | D27: =IF($C27="","",IFERROR(VLOOKUP($C27,Map_Register!$A$2:$C$5,3,FALSE()),"")) -> Toponym Labels | E27: Toponym | F27: 102015 | G27: Landscape | H27: Jaral de Pagola | I27: Basque | J27: Absent | K27: Yes | L27: No | M27: Label not found; enough space for label; generalization is unlikely- space for label is available | N27: No | Q27: https://centrodedescargas.cnig.es/CentroDescargas/btn-poi
A28: =IF($B28="","",ROW()-1) -> 27 | B28: IGN | C28: IGN-04 | D28: =IF($C28="","",IFERROR(VLOOKUP($C28,Map_Register!$A$2:$C$5,3,FALSE()),"")) -> Toponym Labels | E28: Toponym | F28: 102063 | G28: Landscape | H28: Olistieta | I28: Basque | J28: Absent | K28: Yes | L28: No | M28: Label not found; enough space for label; generalization is unlikely- space for label is available | N28: No | Q28: https://centrodedescargas.cnig.es/CentroDescargas/btn-poi
A29: =IF($B29="","",ROW()-1) -> 28 | B29: IGN | C29: IGN-04 | D29: =IF($C29="","",IFERROR(VLOOKUP($C29,Map_Register!$A$2:$C$5,3,FALSE()),"")) -> Toponym Labels | E29: Toponym | F29: 102064 | G29: Landscape | H29: Benaitxoro | I29: Basque | J29: Present | M29: labelled as landscape | Q29: https://centrodedescargas.cnig.es/CentroDescargas/btn-poi
A30: =IF($B30="","",ROW()-1) -> 29 | B30: IGN | C30: IGN-04 | D30: =IF($C30="","",IFERROR(VLOOKUP($C30,Map_Register!$A$2:$C$5,3,FALSE()),"")) -> Toponym Labels | E30: Toponym | F30: 102065 | G30: Landscape | H30: Otan | I30: Basque | J30: Present | M30: labelled as landscape | Q30: https://centrodedescargas.cnig.es/CentroDescargas/btn-poi
A31: =IF($B31="","",ROW()-1) -> 30 | B31: IGN | C31: IGN-04 | D31: =IF($C31="","",IFERROR(VLOOKUP($C31,Map_Register!$A$2:$C$5,3,FALSE()),"")) -> Toponym Labels | E31: Toponym | F31: 102066 | G31: Landscape | H31: Ametxoko | I31: Basque | J31: Present | M31: one present as Ametxoko Borda | Q31: https://centrodedescargas.cnig.es/CentroDescargas/btn-poi
A32: =IF($B32="","",ROW()-1) -> 31 | B32: IGN | C32: IGN-04 | D32: =IF($C32="","",IFERROR(VLOOKUP($C32,Map_Register!$A$2:$C$5,3,FALSE()),"")) -> Toponym Labels | E32: Toponym | F32: 102067 | G32: Landscape | H32: Iturla | I32: Basque | J32: Absent | K32: Yes | L32: No | M32: Label not found; enough space for label; generalization is unlikely- space for label is available | N32: No | Q32: https://centrodedescargas.cnig.es/CentroDescargas/btn-poi
A33: =IF($B33="","",ROW()-1) -> 32 | B33: IGN | C33: IGN-04 | D33: =IF($C33="","",IFERROR(VLOOKUP($C33,Map_Register!$A$2:$C$5,3,FALSE()),"")) -> Toponym Labels | E33: Toponym | F33: 102068 | G33: Landscape | H33: Ibintza | I33: Basque | J33: Present | M33: labelled as landscape | Q33: https://centrodedescargas.cnig.es/CentroDescargas/btn-poi
A34: =IF($B34="","",ROW()-1) -> 33 | B34: IGN | C34: IGN-04 | D34: =IF($C34="","",IFERROR(VLOOKUP($C34,Map_Register!$A$2:$C$5,3,FALSE()),"")) -> Toponym Labels | E34: Toponym | F34: 102072 | G34: Landscape | H34: Mugaosekogaña | I34: Basque | J34: Absent | K34: Yes | L34: Yes | M34: No label found; limited space for label and other labels nearby | N34: No | Q34: https://centrodedescargas.cnig.es/CentroDescargas/btn-poi
A35: =IF($B35="","",ROW()-1) -> 34 | B35: IGN | C35: IGN-04 | D35: =IF($C35="","",IFERROR(VLOOKUP($C35,Map_Register!$A$2:$C$5,3,FALSE()),"")) -> Toponym Labels | E35: Toponym | F35: 102415 | G35: Landscape | H35: Txingorri-Azpie | I35: Basque | J35: Present | M35: labelled as landscape | Q35: https://centrodedescargas.cnig.es/CentroDescargas/btn-poi
A36: =IF($B36="","",ROW()-1) -> 35 | B36: IGN | C36: IGN-04 | D36: =IF($C36="","",IFERROR(VLOOKUP($C36,Map_Register!$A$2:$C$5,3,FALSE()),"")) -> Toponym Labels | E36: Toponym | F36: 102416 | G36: Landscape | H36: Lardi-Lepo | I36: Basque | J36: Present | M36: labelled as landscape | Q36: https://centrodedescargas.cnig.es/CentroDescargas/btn-poi
A37: =IF($B37="","",ROW()-1) -> 36 | B37: IGN | C37: IGN-04 | D37: =IF($C37="","",IFERROR(VLOOKUP($C37,Map_Register!$A$2:$C$5,3,FALSE()),"")) -> Toponym Labels | E37: Toponym | F37: 102417 | G37: Landscape | H37: Zarkinza | I37: Basque | J37: Absent | K37: Yes | L37: No | M37: Label not found; enough space for label; generalization is unlikely- space for label is available | N37: No | Q37: https://centrodedescargas.cnig.es/CentroDescargas/btn-poi
A38: =IF($B38="","",ROW()-1) -> 37 | B38: IGN | C38: IGN-04 | D38: =IF($C38="","",IFERROR(VLOOKUP($C38,Map_Register!$A$2:$C$5,3,FALSE()),"")) -> Toponym Labels | E38: Toponym | F38: 102418 | G38: Landscape | H38: Ikatzola | I38: Basque | J38: Present | M38: labelled as landscape | Q38: https://centrodedescargas.cnig.es/CentroDescargas/btn-poi
A39: =IF($B39="","",ROW()-1) -> 38 | B39: IGN | C39: IGN-04 | D39: =IF($C39="","",IFERROR(VLOOKUP($C39,Map_Register!$A$2:$C$5,3,FALSE()),"")) -> Toponym Labels | E39: Toponym | F39: 102419 | G39: Landscape | H39: Usorbide | I39: Basque | J39: Absent | K39: Yes | L39: No | M39: No name found | N39: No | Q39: https://centrodedescargas.cnig.es/CentroDescargas/btn-poi
A40: =IF($B40="","",ROW()-1) -> 39 | B40: IGN | C40: IGN-04 | D40: =IF($C40="","",IFERROR(VLOOKUP($C40,Map_Register!$A$2:$C$5,3,FALSE()),"")) -> Toponym Labels | E40: Toponym | F40: 102420 | G40: Landscape | H40: Usku | I40: Basque | J40: Present | M40: labelled as landscape | Q40: https://centrodedescargas.cnig.es/CentroDescargas/btn-poi
...

Sheet Spain_Culture
A1: Record_ID | B1: NMA | C1: Map_ID | D1: Sheet_Type | E1: Category | F1: FID | G1: Feature_Type | H1: Name(If Available) | I1: Code | J1: RenderingStage_Flag | K1: Generalization_Flag | L1: Justification | M1: Specification_Flag | N1: Feature_Count | O1: Bertin_Variable | P1: Reference_Source
A2: =IF($B2="","",ROW()-1) -> 1 | B2: IGN | C2: IGN-02 | D2: =IF($C2="","",IFERROR(VLOOKUP($C2,Map_Register!$A$2:$C$5,3,FALSE()),"")) -> Cultural Heritage Area | E2: Cultural | F2: 170 | G2: Conjunto histórico | H2: Conjunto Histórico de Sevilla | I2: Absent | J2: Yes | K2: No | L2: no label or symbol found | M2: No | P2: https://centrodedescargas.cnig.es/CentroDescargas/detalleArchivo?sec=12165696
A3: =IF($B3="","",ROW()-1) -> 2 | B3: IGN | C3: IGN-02 | D3: =IF($C3="","",IFERROR(VLOOKUP($C3,Map_Register!$A$2:$C$5,3,FALSE()),"")) -> Cultural Heritage Area | E3: Cultural | F3: 239 | G3: Monumento | H3: Monte Gurugú | I3: Absent | J3: Yes | K3: Yes | L3: green area, no monument symbol | M3: No | P3: https://centrodedescargas.cnig.es/CentroDescargas/detalleArchivo?sec=12165697
A4: =IF($B4="","",ROW()-1) -> 3 | B4: IGN | C4: IGN-02 | D4: =IF($C4="","",IFERROR(VLOOKUP($C4,Map_Register!$A$2:$C$5,3,FALSE()),"")) -> Cultural Heritage Area | E4: Cultural | F4: 529 | G4: Monumento | H4: Estatua de Bécquer | I4: Absent | J4: Yes | K4: Yes | L4: statue seems to be small | M4: No | P4: https://centrodedescargas.cnig.es/CentroDescargas/detalleArchivo?sec=12165698
A5: =IF($B5="","",ROW()-1) -> 4 | B5: IGN | C5: IGN-02 | D5: =IF($C5="","",IFERROR(VLOOKUP($C5,Map_Register!$A$2:$C$5,3,FALSE()),"")) -> Cultural Heritage Area | E5: Cultural | F5: 586 | G5: Monumento | H5: Airbus | I5: Absent | J5: Yes | K5: Yes | L5: most likely due to size | M5: No | P5: https://centrodedescargas.cnig.es/CentroDescargas/detalleArchivo?sec=12165699
A6: =IF($B6="","",ROW()-1) -> 5 | B6: IGN | C6: IGN-02 | D6: =IF($C6="","",IFERROR(VLOOKUP($C6,Map_Register!$A$2:$C$5,3,FALSE()),"")) -> Cultural Heritage Area | E6: Cultural | F6: 587 | G6: Monumento | H6: Monumento a Simón Bolívar | I6: Absent | J6: Yes | K6: Yes | L6: statue monument | M6: No | P6: https://centrodedescargas.cnig.es/CentroDescargas/detalleArchivo?sec=12165700
A7: =IF($B7="","",ROW()-1) -> 6 | B7: IGN | C7: IGN-02 | D7: =IF($C7="","",IFERROR(VLOOKUP($C7,Map_Register!$A$2:$C$5,3,FALSE()),"")) -> Cultural Heritage Area | E7: Cultural | F7: 588 | G7: Monumento | H7: Monumento a Juan Sebastián Elcano | I7: Absent | J7: Yes | K7: Yes | L7: most likely due to size ; since it’s a small monument(statue) | M7: No | P7: https://centrodedescargas.cnig.es/CentroDescargas/detalleArchivo?sec=12165701
A8: =IF($B8="","",ROW()-1) -> 7 | B8: IGN | C8: IGN-02 | D8: =IF($C8="","",IFERROR(VLOOKUP($C8,Map_Register!$A$2:$C$5,3,FALSE()),"")) -> Cultural Heritage Area | E8: Cultural | F8: 589 | G8: Monumento | H8: Triunfo del Corazón de María | I8: Absent | J8: Yes | K8: Yes | L8: most likely due to size ; since it’s a small monument(statue) | M8: No | P8: https://centrodedescargas.cnig.es/CentroDescargas/detalleArchivo?sec=12165702
A9: =IF($B9="","",ROW()-1) -> 8 | B9: IGN | C9: IGN-02 | D9: =IF($C9="","",IFERROR(VLOOKUP($C9,Map_Register!$A$2:$C$5,3,FALSE()),"")) -> Cultural Heritage Area | E9: Cultural | F9: 594 | G9: Monumento | H9: Monumento a Juan Manuel Rodríguez Ojeda | I9: Absent | J9: Yes | K9: Yes | L9: size | M9: No | P9: https://centrodedescargas.cnig.es/CentroDescargas/detalleArchivo?sec=12165703
A10: =IF($B10="","",ROW()-1) -> 9 | B10: IGN | C10: IGN-02 | D10: =IF($C10="","",IFERROR(VLOOKUP($C10,Map_Register!$A$2:$C$5,3,FALSE()),"")) -> Cultural Heritage Area | E10: Cultural | F10: 595 | G10: Monumento | H10: Cohete Ariane 4 | I10: Absent | J10: Yes | K10: Yes | L10: size | M10: No | P10: https://centrodedescargas.cnig.es/CentroDescargas/detalleArchivo?sec=12165704
A11: =IF($B11="","",ROW()-1) -> 10 | B11: IGN | C11: IGN-02 | D11: =IF($C11="","",IFERROR(VLOOKUP($C11,Map_Register!$A$2:$C$5,3,FALSE()),"")) -> Cultural Heritage Area | E11: Cultural | F11: 597 | G11: Monumento | H11: Antena Instituto de Astrofísica de Canarias Expo 92 | I11: Absent | J11: Yes | K11: Yes | L11: size | M11: No | P11: https://centrodedescargas.cnig.es/CentroDescargas/detalleArchivo?sec=12165705
A12: =IF($B12="","",ROW()-1) -> 11 | B12: IGN | C12: IGN-02 | D12: =IF($C12="","",IFERROR(VLOOKUP($C12,Map_Register!$A$2:$C$5,3,FALSE()),"")) -> Cultural Heritage Area | E12: Cultural | F12: 613 | G12: Monumento | H12: Avión Saeta | I12: Present | L12: historic wall | P12: https://centrodedescargas.cnig.es/CentroDescargas/detalleArchivo?sec=12165706
A13: =IF($B13="","",ROW()-1) -> 12 | B13: IGN | C13: IGN-02 | D13: =IF($C13="","",IFERROR(VLOOKUP($C13,Map_Register!$A$2:$C$5,3,FALSE()),"")) -> Cultural Heritage Area | E13: Cultural | F13: 614 | G13: Monumento | H13: Monumento al Sagrado Corazón de Jesús | I13: Absent | J13: Yes | K13: Yes | L13: empty space, no symbol for monument | M13: No | P13: https://centrodedescargas.cnig.es/CentroDescargas/detalleArchivo?sec=12165707
A14: =IF($B14="","",ROW()-1) -> 13 | B14: IGN | C14: IGN-02 | D14: =IF($C14="","",IFERROR(VLOOKUP($C14,Map_Register!$A$2:$C$5,3,FALSE()),"")) -> Cultural Heritage Area | E14: Cultural | F14: 615 | G14: Monumento | H14: Lugar del Fusilamiento de Blas Infante | I14: Absent | J14: Yes | K14: Yes | L14: size | M14: No | P14: https://centrodedescargas.cnig.es/CentroDescargas/detalleArchivo?sec=12165708
A15: =IF($B15="","",ROW()-1) -> 14 | B15: IGN | C15: IGN-02 | D15: =IF($C15="","",IFERROR(VLOOKUP($C15,Map_Register!$A$2:$C$5,3,FALSE()),"")) -> Cultural Heritage Area | E15: Cultural | F15: 678 | G15: Monumento | H15: Monumento a Cristóbal Colón | I15: Absent | J15: Yes | K15: Yes | L15: most likely due to size ; since it’s a small monument(statue) | M15: No | P15: https://centrodedescargas.cnig.es/CentroDescargas/detalleArchivo?sec=12165709
A16: =IF($B16="","",ROW()-1) -> 15 | B16: IGN | C16: IGN-02 | D16: =IF($C16="","",IFERROR(VLOOKUP($C16,Map_Register!$A$2:$C$5,3,FALSE()),"")) -> Cultural Heritage Area | E16: Cultural | F16: 679 | G16: Monumento | H16: Estatua Aníbal González | I16: Absent | J16: Yes | K16: Yes | L16: most likely due to size ; since it’s a small monument(statue) | M16: No | P16: https://centrodedescargas.cnig.es/CentroDescargas/detalleArchivo?sec=12165710
A17: =IF($B17="","",ROW()-1) -> 16 | B17: IGN | C17: IGN-02 | D17: =IF($C17="","",IFERROR(VLOOKUP($C17,Map_Register!$A$2:$C$5,3,FALSE()),"")) -> Cultural Heritage Area | E17: Cultural | F17: 680 | G17: Monumento | H17: Monumento al Cid Campeador | I17: Absent | J17: Yes | K17: Yes | L17: size | M17: No | P17: https://centrodedescargas.cnig.es/CentroDescargas/detalleArchivo?sec=12165711
A18: =IF($B18="","",ROW()-1) -> 17 | B18: IGN | C18: IGN-02 | D18: =IF($C18="","",IFERROR(VLOOKUP($C18,Map_Register!$A$2:$C$5,3,FALSE()),"")) -> Cultural Heritage Area | E18: Cultural | F18: 681 | G18: Monumento | H18: Piedra Llorosa | I18: Absent | J18: Yes | K18: Yes | L18: size | M18: No | P18: https://centrodedescargas.cnig.es/CentroDescargas/detalleArchivo?sec=12165712
A19: =IF($B19="","",ROW()-1) -> 18 | B19: IGN | C19: IGN-02 | D19: =IF($C19="","",IFERROR(VLOOKUP($C19,Map_Register!$A$2:$C$5,3,FALSE()),"")) -> Cultural Heritage Area | E19: Cultural | F19: 682 | G19: Monumento | H19: Réplica del Giraldillo | I19: Absent | J19: Yes | K19: Yes | L19: most likely due to size ; since it’s a small monument(statue) | M19: No | P19: https://centrodedescargas.cnig.es/CentroDescargas/detalleArchivo?sec=12165713
A20: =IF($B20="","",ROW()-1) -> 19 | B20: IGN | C20: IGN-02 | D20: =IF($C20="","",IFERROR(VLOOKUP($C20,Map_Register!$A$2:$C$5,3,FALSE()),"")) -> Cultural Heritage Area | E20: Cultural | F20: 683 | G20: Monumento | H20: Monumento a la Inmaculada Concepción | I20: Absent | J20: Yes | K20: Yes | L20: size | M20: No | P20: https://centrodedescargas.cnig.es/CentroDescargas/detalleArchivo?sec=12165714
A21: =IF($B21="","",ROW()-1) -> 20 | B21: IGN | C21: IGN-02 | D21: =IF($C21="","",IFERROR(VLOOKUP($C21,Map_Register!$A$2:$C$5,3,FALSE()),"")) -> Cultural Heritage Area | E21: Cultural | F21: 3049 | G21: Muralla | H21: Muralla de la Macarena | I21: Present | L21: historic wall | P21: https://centrodedescargas.cnig.es/CentroDescargas/detalleArchivo?sec=12165715
A22: =IF($B22="","",ROW()-1) -> 21 | B22: IGN | C22: IGN-02 | D22: =IF($C22="","",IFERROR(VLOOKUP($C22,Map_Register!$A$2:$C$5,3,FALSE()),"")) -> Cultural Heritage Area | E22: Cultural | F22: 3050 | G22: Muralla | H22: Murallas de San Juan | I22: Present | L22: historical wall | P22: https://centrodedescargas.cnig.es/CentroDescargas/detalleArchivo?sec=12165716
A23: =IF($B23="","",ROW()-1) -> 22 | B23: IGN | C23: IGN-02 | D23: =IF($C23="","",IFERROR(VLOOKUP($C23,Map_Register!$A$2:$C$5,3,FALSE()),"")) -> Cultural Heritage Area | E23: Cultural | F23: 4378 | G23: Fortaleza/castillo | H23: Castillo de Alcalá de Guadaíra | I23: Present | L23: castle symbolized by historic walls | P23: https://centrodedescargas.cnig.es/CentroDescargas/detalleArchivo?sec=12165717
A24: =IF($B24="","",ROW()-1) -> 23 | B24: IGN | C24: IGN-02 | D24: =IF($C24="","",IFERROR(VLOOKUP($C24,Map_Register!$A$2:$C$5,3,FALSE()),"")) -> Cultural Heritage Area | E24: Cultural | F24: 6751 | G24: Restos arqueológicos | H24: Dolmen de Montelirio | I24: Present | L24: archeological site | P24: https://centrodedescargas.cnig.es/CentroDescargas/detalleArchivo?sec=12165718
A25: =IF($B25="","",ROW()-1) -> 24 | B25: IGN | C25: IGN-02 | D25: =IF($C25="","",IFERROR(VLOOKUP($C25,Map_Register!$A$2:$C$5,3,FALSE()),"")) -> Cultural Heritage Area | E25: Cultural | F25: 6752 | G25: Restos arqueológicos | H25: Yacimiento Arqueológico del Carambolo | I25: Present | L25: archaeological remains | P25: https://centrodedescargas.cnig.es/CentroDescargas/detalleArchivo?sec=12165719
A26: =IF($B26="","",ROW()-1) -> 25 | B26: IGN | C26: IGN-02 | D26: =IF($C26="","",IFERROR(VLOOKUP($C26,Map_Register!$A$2:$C$5,3,FALSE()),"")) -> Cultural Heritage Area | E26: Cultural | F26: 6766 | G26: Restos arqueológicos | H26: Dolmen de Matarrubilla | I26: Present | L26: archaeological remains | P26: https://centrodedescargas.cnig.es/CentroDescargas/detalleArchivo?sec=12165720
A27: =IF($B27="","",ROW()-1) -> 26 | B27: IGN | C27: IGN-02 | D27: =IF($C27="","",IFERROR(VLOOKUP($C27,Map_Register!$A$2:$C$5,3,FALSE()),"")) -> Cultural Heritage Area | E27: Cultural | F27: 6768 | G27: Restos arqueológicos | H27: Dolmen de la Pastora | I27: Present | L27: archeological site | P27: https://centrodedescargas.cnig.es/CentroDescargas/detalleArchivo?sec=12165721
A28: =IF($B28="","",ROW()-1) -> 27 | B28: IGN | C28: IGN-02 | D28: =IF($C28="","",IFERROR(VLOOKUP($C28,Map_Register!$A$2:$C$5,3,FALSE()),"")) -> Cultural Heritage Area | E28: Cultural | F28: 7298 | G28: Restos arqueológicos | H28: Conjunto Arqueológico de Itálica | I28: Present | L28: archaeological remains; label presen | P28: https://centrodedescargas.cnig.es/CentroDescargas/detalleArchivo?sec=12165722
A29: =IF($B29="","",ROW()-1) -> 28 | B29: IGN | C29: IGN-02 | D29: =IF($C29="","",IFERROR(VLOOKUP($C29,Map_Register!$A$2:$C$5,3,FALSE()),"")) -> Cultural Heritage Area | E29: Cultural | F29: 19129 | G29: Muralla | H29: Muralla de Itálica | I29: Present | L29: historical wall | P29: https://centrodedescargas.cnig.es/CentroDescargas/detalleArchivo?sec=12165723
A30: =IF($B30="","",ROW()-1) -> 29 | B30: IGN | C30: IGN-02 | D30: =IF($C30="","",IFERROR(VLOOKUP($C30,Map_Register!$A$2:$C$5,3,FALSE()),"")) -> Cultural Heritage Area | E30: Cultural | F30: 19131 | G30: Monumento | H30: Monumento a Andalucía | I30: Absent | J30: Yes | K30: Yes | L30: empty space, no symbol for monument | M30: No | P30: https://centrodedescargas.cnig.es/CentroDescargas/detalleArchivo?sec=12165724
A31: =IF($B31="","",ROW()-1) -> 30 | B31: IGN | C31: IGN-02 | D31: =IF($C31="","",IFERROR(VLOOKUP($C31,Map_Register!$A$2:$C$5,3,FALSE()),"")) -> Cultural Heritage Area | E31: Cultural | F31: 19272 | G31: Restos arqueológicos | H31: Casa de Cañada Honda | I31: Present | L31: arch site | P31: https://centrodedescargas.cnig.es/CentroDescargas/detalleArchivo?sec=12165725
A32: =IF($B32="","",ROW()-1) -> 31 | B32: IGN | C32: IGN-02 | D32: =IF($C32="","",IFERROR(VLOOKUP($C32,Map_Register!$A$2:$C$5,3,FALSE()),"")) -> Cultural Heritage Area | E32: Cultural | F32: 20065 | G32: Restos arqueológicos | H32: Casa del Planetario | I32: Present | L32: archaeological remains | P32: https://centrodedescargas.cnig.es/CentroDescargas/detalleArchivo?sec=12165726
A33: =IF($B33="","",ROW()-1) -> 32 | B33: IGN | C33: IGN-02 | D33: =IF($C33="","",IFERROR(VLOOKUP($C33,Map_Register!$A$2:$C$5,3,FALSE()),"")) -> Cultural Heritage Area | E33: Cultural | F33: 25511 | G33: Monumento | H33: Estatua a El Bombita | I33: Absent | J33: Yes | K33: Yes | L33: size | M33: No | P33: https://centrodedescargas.cnig.es/CentroDescargas/detalleArchivo?sec=12165727
A34: =IF($B34="","",ROW()-1) -> 33 | B34: IGN | C34: IGN-02 | D34: =IF($C34="","",IFERROR(VLOOKUP($C34,Map_Register!$A$2:$C$5,3,FALSE()),"")) -> Cultural Heritage Area | E34: Cultural | F34: 27083 | G34: Monumento | H34: Monumento a los Marineros Voluntarios | I34: Absent | J34: Yes | K34: Yes | L34: size | M34: No | P34: https://centrodedescargas.cnig.es/CentroDescargas/detalleArchivo?sec=12165728
A35: =IF($B35="","",ROW()-1) -> 34 | B35: IGN | C35: IGN-02 | D35: =IF($C35="","",IFERROR(VLOOKUP($C35,Map_Register!$A$2:$C$5,3,FALSE()),"")) -> Cultural Heritage Area | E35: Cultural | F35: 27086 | G35: Monumento | H35: El Lápiz | I35: Absent | J35: Yes | K35: Yes | L35: size | M35: No | P35: https://centrodedescargas.cnig.es/CentroDescargas/detalleArchivo?sec=12165729
A36: =IF($B36="","",ROW()-1) -> 35 | B36: IGN | C36: IGN-02 | D36: =IF($C36="","",IFERROR(VLOOKUP($C36,Map_Register!$A$2:$C$5,3,FALSE()),"")) -> Cultural Heritage Area | E36: Cultural | F36: 27087 | G36: Monumento | H36: Monumento Columnas de Hércules | I36: Absent | J36: Yes | K36: Yes | L36: size | M36: No | P36: https://centrodedescargas.cnig.es/CentroDescargas/detalleArchivo?sec=12165730
A37: =IF($B37="","",ROW()-1) -> 36 | B37: IGN | C37: IGN-02 | D37: =IF($C37="","",IFERROR(VLOOKUP($C37,Map_Register!$A$2:$C$5,3,FALSE()),"")) -> Cultural Heritage Area | E37: Cultural | F37: 27088 | G37: Monumento | H37: Estatua San Juan Bautista de la Salle | I37: Absent | J37: Yes | K37: Yes | L37: size | M37: No | P37: https://centrodedescargas.cnig.es/CentroDescargas/detalleArchivo?sec=12165731
A38: =IF($B38="","",ROW()-1) -> 37 | B38: IGN | C38: IGN-02 | D38: =IF($C38="","",IFERROR(VLOOKUP($C38,Map_Register!$A$2:$C$5,3,FALSE()),"")) -> Cultural Heritage Area | E38: Cultural | F38: 28207 | G38: Monumento | H38: Atomium | I38: Absent | J38: Yes | K38: Yes | L38: most likely due to size ; since it’s a small monument(statue) | M38: No | P38: https://centrodedescargas.cnig.es/CentroDescargas/detalleArchivo?sec=12165732
A39: =IF($B39="","",ROW()-1) -> 38 | B39: IGN | C39: IGN-02 | D39: =IF($C39="","",IFERROR(VLOOKUP($C39,Map_Register!$A$2:$C$5,3,FALSE()),"")) -> Cultural Heritage Area | E39: Cultural | F39: 38477 | G39: Monumento | H39: Monumento a Santa Ángela de la Cruz | I39: Absent | J39: Yes | K39: Yes | L39: most likely due to size ; since it’s a small monument(statue) | M39: No | P39: https://centrodedescargas.cnig.es/CentroDescargas/detalleArchivo?sec=12165733
A40: =IF($B40="","",ROW()-1) -> 39 | B40: IGN | C40: IGN-02 | D40: =IF($C40="","",IFERROR(VLOOKUP($C40,Map_Register!$A$2:$C$5,3,FALSE()),"")) -> Cultural Heritage Area | E40: Cultural | F40: 38719 | G40: Monumento | H40: Puerta del Perdón | I40: Absent | J40: Yes | K40: Yes | L40: part of building | M40: No | P40: https://centrodedescargas.cnig.es/CentroDescargas/detalleArchivo?sec=12165734
...

Sheet Summary
A1: Spain Representation Inventory — Summary of Coding Results
A2: National Mapping Agency: IGN | Auto-summarized from the Coding_Records sheets (Table 7 instrument, Section 3.5). Figures recalculate automatically as records are added.
A3: Note: 'Present' totals include emphasized features (Code beginning "Present"); 'Absent' totals include minor spelling/case variants (Code beginning "Absent"); 'Other/Unclear' captures any remaining codes (e.g. "outside sheet extent").
A5: 1. Overall Coding Results by Category
A6: Category | B6: Total Records | C6: Present | D6: Present (Emphasized) | E6: Absent | F6: Other / Unclear | G6: % Present | H6: % Absent
A7: Culture | B7: =COUNTA(Spain_Culture!I2:I503) -> 249 | C7: =COUNTIF(Spain_Culture!I2:I503,"Present*")-COUNTIF(Spain_Culture!I2:I503,"*Emphasi*") -> 89 | D7: =COUNTIF(Spain_Culture!I2:I503,"*Emphasi*") -> 12 | E7: =COUNTIF(Spain_Culture!I2:I503,"Absent*") -> 145 | F7: =B7-C7-D7-E7 -> 3 | G7: =IF(B7=0,0,(C7+D7)/B7) -> 0.40562249 | H7: =IF(B7=0,0,E7/B7) -> 0.58232932
A8: Border | B8: =COUNTA(Spain_Border!H2:H61) -> 60 | C8: =COUNTIF(Spain_Border!H2:H61,"Present*")-COUNTIF(Spain_Border!H2:H61,"*Emphasi*") -> 52 | D8: =COUNTIF(Spain_Border!H2:H61,"*Emphasi*") -> 1 | E8: =COUNTIF(Spain_Border!H2:H61,"Absent*") -> 7 | F8: =B8-C8-D8-E8 -> 0 | G8: =IF(B8=0,0,(C8+D8)/B8) -> 0.88333333 | H8: =IF(B8=0,0,E8/B8) -> 0.11666667
A9: Military | B9: =COUNTA(Spain_Military!H2:H9) -> 8 | C9: =COUNTIF(Spain_Military!H2:H9,"Present*")-COUNTIF(Spain_Military!H2:H9,"*Emphasi*") -> 5 | D9: =COUNTIF(Spain_Military!H2:H9,"*Emphasi*") -> 0 | E9: =COUNTIF(Spain_Military!H2:H9,"Absent*") -> 3 | F9: =B9-C9-D9-E9 -> 0 | G9: =IF(B9=0,0,(C9+D9)/B9) -> 0.625 | H9: =IF(B9=0,0,E9/B9) -> 0.375
A10: Toponym | B10: =COUNTA(Spain_Toponym!J2:J1833) -> 1832 | C10: =COUNTIF(Spain_Toponym!J2:J1833,"Present*")-COUNTIF(Spain_Toponym!J2:J1833,"*Emphasi*") -> 1075 | D10: =COUNTIF(Spain_Toponym!J2:J1833,"*Emphasi*") -> 64 | E10: =COUNTIF(Spain_Toponym!J2:J1833,"Absent*") -> 693 | F10: =B10-C10-D10-E10 -> 0 | G10: =IF(B10=0,0,(C10+D10)/B10) -> 0.62172489 | H10: =IF(B10=0,0,E10/B10) -> 0.37827511
A11: TOTAL | B11: =SUM(B7:B10) -> 2149 | C11: =SUM(C7:C10) -> 1221 | D11: =SUM(D7:D10) -> 77 | E11: =SUM(E7:E10) -> 848 | G11: =IF(B11=0,0,(C11+D11)/B11) -> 0.60400186 | H11: =IF(B11=0,0,E11/B11) -> 0.39460214
A13: 2. Visual Emphasis Analysis (share of Present features that are emphasized)
A14: Category | B14: Present (Total, incl. emphasized) | C14: Present (Emphasized) | D14: % of Present Emphasized
A15: Culture | B15: =C7+D7 -> 101 | C15: =D7 -> 12 | D15: =IF(B15=0,0,C15/B15) -> 0.11881188
A16: Border | B16: =C8+D8 -> 53 | C16: =D8 -> 1 | D16: =IF(B16=0,0,C16/B16) -> 0.018867925
A17: Military | B17: =C9+D9 -> 5 | C17: =D9 -> 0 | D17: =IF(B17=0,0,C17/B17) -> 0
A18: Toponym | B18: =C10+D10 -> 1139 | C18: =D10 -> 64 | D18: =IF(B18=0,0,C18/B18) -> 0.05618964
A19: TOTAL | B19: =SUM(B15:B18) -> 1298 | C19: =SUM(C15:C18) -> 77 | D19: =IF(B19=0,0,C19/B19) -> 0.059322034
A21: 3. Absence-Reason Flag Analysis (basis coded for Absent features)
A22: Category | B22: Absent Total | C22: Rendering-Stage Omission (Yes) | D22: Specification Gap (Yes) | E22: Generalization- Attributed (Yes)
A23: Culture | B23: =E7 -> 145 | C23: =COUNTIF(Spain_Culture!J2:J503,"*Yes*") -> 144 | D23: =COUNTIF(Spain_Culture!M2:M503,"*Yes*") -> 0 | E23: =COUNTIF(Spain_Culture!K2:K503,"*Yes*") -> 139
A24: Border | B24: =E8 -> 7 | C24: =COUNTIF(Spain_Border!I2:I61,"*Yes*") -> 5 | D24: =COUNTIF(Spain_Border!L2:L61,"*Yes*") -> 1 | E24: =COUNTIF(Spain_Border!J2:J61,"*Yes*") -> 6
A25: Military | B25: =E9 -> 3 | C25: =COUNTIF(Spain_Military!I2:I9,"*Yes*") -> 0 | D25: =COUNTIF(Spain_Military!L2:L9,"*Yes*") -> 3 | E25: =COUNTIF(Spain_Military!J2:J9,"*Yes*") -> 0
A26: Toponym | B26: =E10 -> 693 | C26: =COUNTIF(Spain_Toponym!K2:K1833,"*Yes*") -> 691 | D26: =COUNTIF(Spain_Toponym!N2:N1833,"*Yes*") -> 0 | E26: =COUNTIF(Spain_Toponym!L2:L1833,"*Yes*") -> 311
A27: TOTAL | B27: =SUM(B23:B26) -> 848 | C27: =SUM(C23:C26) -> 840 | D27: =SUM(D23:D26) -> 4 | E27: =SUM(E23:E26) -> 456
A29: Note: a record may carry more than one flag, so flag counts need not sum to the Absent total; N/A and blank entries are excluded from these counts.
A31: 4. Coding Coverage by Map Sample
A32: Map ID | B32: Area / Context | C32: Sheet Type | D32: Total Records | E32: Present | F32: Absent | G32: % Absent
